Watching for file changes with StatReloader
Watching for file changes with StatReloader
"GET / HTTP/1.1" 200 18170
"GET / HTTP/1.1" 200 18170
"GET /static/vendor/font-awesome/css/font-awesome.min.css HTTP/1.1" 200 31396
"GET /static/vendor/font-awesome/css/font-awesome.min.css HTTP/1.1" 200 31396
"GET /static/vendor/owl.carousel/assets/owl.carousel.css HTTP/1.1" 200 4744
"GET /static/vendor/owl.carousel/assets/owl.carousel.css HTTP/1.1" 200 4744
"GET /static/vendor/owl.carousel/assets/owl.theme.default.css HTTP/1.1" 200 1380
"GET /static/vendor/owl.carousel/assets/owl.theme.default.css HTTP/1.1" 200 1380
"GET /static/vendor/bootstrap/css/bootstrap.min.css HTTP/1.1" 200 140930
"GET /static/vendor/bootstrap/css/bootstrap.min.css HTTP/1.1" 200 140930
"GET /static/css/custom.css HTTP/1.1" 200 25
"GET /static/css/custom.css HTTP/1.1" 200 25
"GET /static/css/style.default.css HTTP/1.1" 200 57334
"GET /static/css/style.default.css HTTP/1.1" 200 57334
"GET /static/vendor/jquery/jquery.min.js HTTP/1.1" 200 86927
"GET /static/vendor/jquery/jquery.min.js HTTP/1.1" 200 86927
"GET /static/vendor/popper.js/umd/popper.min.js HTTP/1.1" 200 20337
"GET /static/vendor/popper.js/umd/popper.min.js HTTP/1.1" 200 20337
"GET /static/vendor/bootstrap/js/bootstrap.min.js HTTP/1.1" 200 50731
"GET /static/vendor/bootstrap/js/bootstrap.min.js HTTP/1.1" 200 50731
"GET /static/vendor/bootstrap-select/js/bootstrap-select.min.js HTTP/1.1" 200 44448
"GET /static/vendor/bootstrap-select/js/bootstrap-select.min.js HTTP/1.1" 200 44448
"GET /static/vendor/owl.carousel/owl.carousel.min.js HTTP/1.1" 200 44342
"GET /static/vendor/owl.carousel/owl.carousel.min.js HTTP/1.1" 200 44342
"GET /static/vendor/jquery.cookie/jquery.cookie.js HTTP/1.1" 200 3121
"GET /static/vendor/jquery.cookie/jquery.cookie.js HTTP/1.1" 200 3121
"GET /static/img/company-1.png HTTP/1.1" 200 3494
"GET /static/img/company-1.png HTTP/1.1" 200 3494
"GET /static/js/front.js HTTP/1.1" 200 8053
"GET /static/js/front.js HTTP/1.1" 200 8053
"GET /static/img/logo-small.png HTTP/1.1" 200 5152
"GET /static/img/logo-small.png HTTP/1.1" 200 5152
"GET /static/img/featured1.jpg HTTP/1.1" 200 121881
"GET /static/img/featured1.jpg HTTP/1.1" 200 121881
"GET /static/img/meeting.jpg HTTP/1.1" 200 144248
"GET /static/img/meeting.jpg HTTP/1.1" 200 144248
"GET /static/img/startup.jpg HTTP/1.1" 404 1671
"GET /static/img/startup.jpg HTTP/1.1" 404 1671
Not Found: /favicon.png
Not Found: /favicon.png
"GET /favicon.png HTTP/1.1" 404 4396
"GET /favicon.png HTTP/1.1" 404 4396
/home/rumi/Desktop/projects/my_jobs_env/django-job-portal/jobs/settings.py changed, reloading.
/home/rumi/Desktop/projects/my_jobs_env/django-job-portal/jobs/settings.py changed, reloading.
Watching for file changes with StatReloader
Watching for file changes with StatReloader
Internal Server Error: /api/jobs/
Traceback (most recent call last):
  File "/home/rumi/Desktop/projects/my_jobs_env/lib/python3.6/site-packages/rest_framework/views.py", line 493, in dispatch
    self.initial(request, *args, **kwargs)
  File "/home/rumi/Desktop/projects/my_jobs_env/lib/python3.6/site-packages/rest_framework/views.py", line 411, in initial
    self.check_permissions(request)
  File "/home/rumi/Desktop/projects/my_jobs_env/lib/python3.6/site-packages/rest_framework/views.py", line 334, in check_permissions
    request, message=getattr(permission, 'message', None)
  File "/home/rumi/Desktop/projects/my_jobs_env/lib/python3.6/site-packages/rest_framework/views.py", line 174, in permission_denied
    raise exceptions.NotAuthenticated()
rest_framework.exceptions.NotAuthenticated: Authentication credentials were not provided.

During handling of the above exception, another exception occurred:

Traceback (most recent call last):
  File "/home/rumi/Desktop/projects/my_jobs_env/lib/python3.6/site-packages/rest_framework/settings.py", line 177, in import_from_string
    return import_string(val)
  File "/home/rumi/Desktop/projects/my_jobs_env/lib/python3.6/site-packages/django/utils/module_loading.py", line 17, in import_string
    module = import_module(module_path)
  File "/home/rumi/Desktop/projects/my_jobs_env/lib/python3.6/importlib/__init__.py", line 126, in import_module
    return _bootstrap._gcd_import(name[level:], package, level)
  File "<frozen importlib._bootstrap>", line 994, in _gcd_import
  File "<frozen importlib._bootstrap>", line 971, in _find_and_load
  File "<frozen importlib._bootstrap>", line 941, in _find_and_load_unlocked
  File "<frozen importlib._bootstrap>", line 219, in _call_with_frames_removed
  File "<frozen importlib._bootstrap>", line 994, in _gcd_import
  File "<frozen importlib._bootstrap>", line 971, in _find_and_load
  File "<frozen importlib._bootstrap>", line 941, in _find_and_load_unlocked
  File "<frozen importlib._bootstrap>", line 219, in _call_with_frames_removed
  File "<frozen importlib._bootstrap>", line 994, in _gcd_import
  File "<frozen importlib._bootstrap>", line 971, in _find_and_load
  File "<frozen importlib._bootstrap>", line 953, in _find_and_load_unlocked
ModuleNotFoundError: No module named 'core'

During handling of the above exception, another exception occurred:

Traceback (most recent call last):
  File "/home/rumi/Desktop/projects/my_jobs_env/lib/python3.6/site-packages/django/core/handlers/exception.py", line 34, in inner
    response = get_response(request)
  File "/home/rumi/Desktop/projects/my_jobs_env/lib/python3.6/site-packages/django/core/handlers/base.py", line 115, in _get_response
    response = self.process_exception_by_middleware(e, request)
  File "/home/rumi/Desktop/projects/my_jobs_env/lib/python3.6/site-packages/django/core/handlers/base.py", line 113, in _get_response
    response = wrapped_callback(request, *callback_args, **callback_kwargs)
  File "/home/rumi/Desktop/projects/my_jobs_env/lib/python3.6/site-packages/django/views/decorators/csrf.py", line 54, in wrapped_view
    return view_func(*args, **kwargs)
  File "/home/rumi/Desktop/projects/my_jobs_env/lib/python3.6/site-packages/rest_framework/viewsets.py", line 114, in view
    return self.dispatch(request, *args, **kwargs)
  File "/home/rumi/Desktop/projects/my_jobs_env/lib/python3.6/site-packages/rest_framework/views.py", line 505, in dispatch
    response = self.handle_exception(exc)
  File "/home/rumi/Desktop/projects/my_jobs_env/lib/python3.6/site-packages/rest_framework/views.py", line 459, in handle_exception
    exception_handler = self.get_exception_handler()
  File "/home/rumi/Desktop/projects/my_jobs_env/lib/python3.6/site-packages/rest_framework/views.py", line 298, in get_exception_handler
    return self.settings.EXCEPTION_HANDLER
  File "/home/rumi/Desktop/projects/my_jobs_env/lib/python3.6/site-packages/rest_framework/settings.py", line 220, in __getattr__
    val = perform_import(val, attr)
  File "/home/rumi/Desktop/projects/my_jobs_env/lib/python3.6/site-packages/rest_framework/settings.py", line 166, in perform_import
    return import_from_string(val, setting_name)
  File "/home/rumi/Desktop/projects/my_jobs_env/lib/python3.6/site-packages/rest_framework/settings.py", line 180, in import_from_string
    raise ImportError(msg)
ImportError: Could not import 'core.api.custom_exception.custom_exception_handler' for API setting 'EXCEPTION_HANDLER'. ModuleNotFoundError: No module named 'core'.
Internal Server Error: /api/jobs/
Traceback (most recent call last):
  File "/home/rumi/Desktop/projects/my_jobs_env/lib/python3.6/site-packages/rest_framework/views.py", line 493, in dispatch
    self.initial(request, *args, **kwargs)
  File "/home/rumi/Desktop/projects/my_jobs_env/lib/python3.6/site-packages/rest_framework/views.py", line 411, in initial
    self.check_permissions(request)
  File "/home/rumi/Desktop/projects/my_jobs_env/lib/python3.6/site-packages/rest_framework/views.py", line 334, in check_permissions
    request, message=getattr(permission, 'message', None)
  File "/home/rumi/Desktop/projects/my_jobs_env/lib/python3.6/site-packages/rest_framework/views.py", line 174, in permission_denied
    raise exceptions.NotAuthenticated()
rest_framework.exceptions.NotAuthenticated: Authentication credentials were not provided.

During handling of the above exception, another exception occurred:

Traceback (most recent call last):
  File "/home/rumi/Desktop/projects/my_jobs_env/lib/python3.6/site-packages/rest_framework/settings.py", line 177, in import_from_string
    return import_string(val)
  File "/home/rumi/Desktop/projects/my_jobs_env/lib/python3.6/site-packages/django/utils/module_loading.py", line 17, in import_string
    module = import_module(module_path)
  File "/home/rumi/Desktop/projects/my_jobs_env/lib/python3.6/importlib/__init__.py", line 126, in import_module
    return _bootstrap._gcd_import(name[level:], package, level)
  File "<frozen importlib._bootstrap>", line 994, in _gcd_import
  File "<frozen importlib._bootstrap>", line 971, in _find_and_load
  File "<frozen importlib._bootstrap>", line 941, in _find_and_load_unlocked
  File "<frozen importlib._bootstrap>", line 219, in _call_with_frames_removed
  File "<frozen importlib._bootstrap>", line 994, in _gcd_import
  File "<frozen importlib._bootstrap>", line 971, in _find_and_load
  File "<frozen importlib._bootstrap>", line 941, in _find_and_load_unlocked
  File "<frozen importlib._bootstrap>", line 219, in _call_with_frames_removed
  File "<frozen importlib._bootstrap>", line 994, in _gcd_import
  File "<frozen importlib._bootstrap>", line 971, in _find_and_load
  File "<frozen importlib._bootstrap>", line 953, in _find_and_load_unlocked
ModuleNotFoundError: No module named 'core'

During handling of the above exception, another exception occurred:

Traceback (most recent call last):
  File "/home/rumi/Desktop/projects/my_jobs_env/lib/python3.6/site-packages/django/core/handlers/exception.py", line 34, in inner
    response = get_response(request)
  File "/home/rumi/Desktop/projects/my_jobs_env/lib/python3.6/site-packages/django/core/handlers/base.py", line 115, in _get_response
    response = self.process_exception_by_middleware(e, request)
  File "/home/rumi/Desktop/projects/my_jobs_env/lib/python3.6/site-packages/django/core/handlers/base.py", line 113, in _get_response
    response = wrapped_callback(request, *callback_args, **callback_kwargs)
  File "/home/rumi/Desktop/projects/my_jobs_env/lib/python3.6/site-packages/django/views/decorators/csrf.py", line 54, in wrapped_view
    return view_func(*args, **kwargs)
  File "/home/rumi/Desktop/projects/my_jobs_env/lib/python3.6/site-packages/rest_framework/viewsets.py", line 114, in view
    return self.dispatch(request, *args, **kwargs)
  File "/home/rumi/Desktop/projects/my_jobs_env/lib/python3.6/site-packages/rest_framework/views.py", line 505, in dispatch
    response = self.handle_exception(exc)
  File "/home/rumi/Desktop/projects/my_jobs_env/lib/python3.6/site-packages/rest_framework/views.py", line 459, in handle_exception
    exception_handler = self.get_exception_handler()
  File "/home/rumi/Desktop/projects/my_jobs_env/lib/python3.6/site-packages/rest_framework/views.py", line 298, in get_exception_handler
    return self.settings.EXCEPTION_HANDLER
  File "/home/rumi/Desktop/projects/my_jobs_env/lib/python3.6/site-packages/rest_framework/settings.py", line 220, in __getattr__
    val = perform_import(val, attr)
  File "/home/rumi/Desktop/projects/my_jobs_env/lib/python3.6/site-packages/rest_framework/settings.py", line 166, in perform_import
    return import_from_string(val, setting_name)
  File "/home/rumi/Desktop/projects/my_jobs_env/lib/python3.6/site-packages/rest_framework/settings.py", line 180, in import_from_string
    raise ImportError(msg)
ImportError: Could not import 'core.api.custom_exception.custom_exception_handler' for API setting 'EXCEPTION_HANDLER'. ModuleNotFoundError: No module named 'core'.
"GET /api/jobs/ HTTP/1.1" 500 155460
"GET /api/jobs/ HTTP/1.1" 500 155460
"GET / HTTP/1.1" 200 18170
"GET / HTTP/1.1" 200 18170
"GET /static/img/startup.jpg HTTP/1.1" 404 1671
"GET /static/img/startup.jpg HTTP/1.1" 404 1671
/home/rumi/Desktop/projects/my_jobs_env/django-job-portal/jobs/wsgi.py changed, reloading.
/home/rumi/Desktop/projects/my_jobs_env/django-job-portal/jobs/wsgi.py changed, reloading.
Watching for file changes with StatReloader
Watching for file changes with StatReloader
"GET / HTTP/1.1" 200 18170
"GET / HTTP/1.1" 200 18170
"GET /static/img/startup.jpg HTTP/1.1" 404 1671
"GET /static/img/startup.jpg HTTP/1.1" 404 1671
Internal Server Error: /api/jobs/
Traceback (most recent call last):
  File "/home/rumi/Desktop/projects/my_jobs_env/lib/python3.6/site-packages/rest_framework/views.py", line 493, in dispatch
    self.initial(request, *args, **kwargs)
  File "/home/rumi/Desktop/projects/my_jobs_env/lib/python3.6/site-packages/rest_framework/views.py", line 411, in initial
    self.check_permissions(request)
  File "/home/rumi/Desktop/projects/my_jobs_env/lib/python3.6/site-packages/rest_framework/views.py", line 334, in check_permissions
    request, message=getattr(permission, 'message', None)
  File "/home/rumi/Desktop/projects/my_jobs_env/lib/python3.6/site-packages/rest_framework/views.py", line 174, in permission_denied
    raise exceptions.NotAuthenticated()
rest_framework.exceptions.NotAuthenticated: Authentication credentials were not provided.

During handling of the above exception, another exception occurred:

Traceback (most recent call last):
  File "/home/rumi/Desktop/projects/my_jobs_env/lib/python3.6/site-packages/rest_framework/settings.py", line 177, in import_from_string
    return import_string(val)
  File "/home/rumi/Desktop/projects/my_jobs_env/lib/python3.6/site-packages/django/utils/module_loading.py", line 17, in import_string
    module = import_module(module_path)
  File "/home/rumi/Desktop/projects/my_jobs_env/lib/python3.6/importlib/__init__.py", line 126, in import_module
    return _bootstrap._gcd_import(name[level:], package, level)
  File "<frozen importlib._bootstrap>", line 994, in _gcd_import
  File "<frozen importlib._bootstrap>", line 971, in _find_and_load
  File "<frozen importlib._bootstrap>", line 941, in _find_and_load_unlocked
  File "<frozen importlib._bootstrap>", line 219, in _call_with_frames_removed
  File "<frozen importlib._bootstrap>", line 994, in _gcd_import
  File "<frozen importlib._bootstrap>", line 971, in _find_and_load
  File "<frozen importlib._bootstrap>", line 941, in _find_and_load_unlocked
  File "<frozen importlib._bootstrap>", line 219, in _call_with_frames_removed
  File "<frozen importlib._bootstrap>", line 994, in _gcd_import
  File "<frozen importlib._bootstrap>", line 971, in _find_and_load
  File "<frozen importlib._bootstrap>", line 953, in _find_and_load_unlocked
ModuleNotFoundError: No module named 'core'

During handling of the above exception, another exception occurred:

Traceback (most recent call last):
  File "/home/rumi/Desktop/projects/my_jobs_env/lib/python3.6/site-packages/django/core/handlers/exception.py", line 34, in inner
    response = get_response(request)
  File "/home/rumi/Desktop/projects/my_jobs_env/lib/python3.6/site-packages/django/core/handlers/base.py", line 115, in _get_response
    response = self.process_exception_by_middleware(e, request)
  File "/home/rumi/Desktop/projects/my_jobs_env/lib/python3.6/site-packages/django/core/handlers/base.py", line 113, in _get_response
    response = wrapped_callback(request, *callback_args, **callback_kwargs)
  File "/home/rumi/Desktop/projects/my_jobs_env/lib/python3.6/site-packages/django/views/decorators/csrf.py", line 54, in wrapped_view
    return view_func(*args, **kwargs)
  File "/home/rumi/Desktop/projects/my_jobs_env/lib/python3.6/site-packages/rest_framework/viewsets.py", line 114, in view
    return self.dispatch(request, *args, **kwargs)
  File "/home/rumi/Desktop/projects/my_jobs_env/lib/python3.6/site-packages/rest_framework/views.py", line 505, in dispatch
    response = self.handle_exception(exc)
  File "/home/rumi/Desktop/projects/my_jobs_env/lib/python3.6/site-packages/rest_framework/views.py", line 459, in handle_exception
    exception_handler = self.get_exception_handler()
  File "/home/rumi/Desktop/projects/my_jobs_env/lib/python3.6/site-packages/rest_framework/views.py", line 298, in get_exception_handler
    return self.settings.EXCEPTION_HANDLER
  File "/home/rumi/Desktop/projects/my_jobs_env/lib/python3.6/site-packages/rest_framework/settings.py", line 220, in __getattr__
    val = perform_import(val, attr)
  File "/home/rumi/Desktop/projects/my_jobs_env/lib/python3.6/site-packages/rest_framework/settings.py", line 166, in perform_import
    return import_from_string(val, setting_name)
  File "/home/rumi/Desktop/projects/my_jobs_env/lib/python3.6/site-packages/rest_framework/settings.py", line 180, in import_from_string
    raise ImportError(msg)
ImportError: Could not import 'core.api.custom_exception.custom_exception_handler' for API setting 'EXCEPTION_HANDLER'. ModuleNotFoundError: No module named 'core'.
Internal Server Error: /api/jobs/
Traceback (most recent call last):
  File "/home/rumi/Desktop/projects/my_jobs_env/lib/python3.6/site-packages/rest_framework/views.py", line 493, in dispatch
    self.initial(request, *args, **kwargs)
  File "/home/rumi/Desktop/projects/my_jobs_env/lib/python3.6/site-packages/rest_framework/views.py", line 411, in initial
    self.check_permissions(request)
  File "/home/rumi/Desktop/projects/my_jobs_env/lib/python3.6/site-packages/rest_framework/views.py", line 334, in check_permissions
    request, message=getattr(permission, 'message', None)
  File "/home/rumi/Desktop/projects/my_jobs_env/lib/python3.6/site-packages/rest_framework/views.py", line 174, in permission_denied
    raise exceptions.NotAuthenticated()
rest_framework.exceptions.NotAuthenticated: Authentication credentials were not provided.

During handling of the above exception, another exception occurred:

Traceback (most recent call last):
  File "/home/rumi/Desktop/projects/my_jobs_env/lib/python3.6/site-packages/rest_framework/settings.py", line 177, in import_from_string
    return import_string(val)
  File "/home/rumi/Desktop/projects/my_jobs_env/lib/python3.6/site-packages/django/utils/module_loading.py", line 17, in import_string
    module = import_module(module_path)
  File "/home/rumi/Desktop/projects/my_jobs_env/lib/python3.6/importlib/__init__.py", line 126, in import_module
    return _bootstrap._gcd_import(name[level:], package, level)
  File "<frozen importlib._bootstrap>", line 994, in _gcd_import
  File "<frozen importlib._bootstrap>", line 971, in _find_and_load
  File "<frozen importlib._bootstrap>", line 941, in _find_and_load_unlocked
  File "<frozen importlib._bootstrap>", line 219, in _call_with_frames_removed
  File "<frozen importlib._bootstrap>", line 994, in _gcd_import
  File "<frozen importlib._bootstrap>", line 971, in _find_and_load
  File "<frozen importlib._bootstrap>", line 941, in _find_and_load_unlocked
  File "<frozen importlib._bootstrap>", line 219, in _call_with_frames_removed
  File "<frozen importlib._bootstrap>", line 994, in _gcd_import
  File "<frozen importlib._bootstrap>", line 971, in _find_and_load
  File "<frozen importlib._bootstrap>", line 953, in _find_and_load_unlocked
ModuleNotFoundError: No module named 'core'

During handling of the above exception, another exception occurred:

Traceback (most recent call last):
  File "/home/rumi/Desktop/projects/my_jobs_env/lib/python3.6/site-packages/django/core/handlers/exception.py", line 34, in inner
    response = get_response(request)
  File "/home/rumi/Desktop/projects/my_jobs_env/lib/python3.6/site-packages/django/core/handlers/base.py", line 115, in _get_response
    response = self.process_exception_by_middleware(e, request)
  File "/home/rumi/Desktop/projects/my_jobs_env/lib/python3.6/site-packages/django/core/handlers/base.py", line 113, in _get_response
    response = wrapped_callback(request, *callback_args, **callback_kwargs)
  File "/home/rumi/Desktop/projects/my_jobs_env/lib/python3.6/site-packages/django/views/decorators/csrf.py", line 54, in wrapped_view
    return view_func(*args, **kwargs)
  File "/home/rumi/Desktop/projects/my_jobs_env/lib/python3.6/site-packages/rest_framework/viewsets.py", line 114, in view
    return self.dispatch(request, *args, **kwargs)
  File "/home/rumi/Desktop/projects/my_jobs_env/lib/python3.6/site-packages/rest_framework/views.py", line 505, in dispatch
    response = self.handle_exception(exc)
  File "/home/rumi/Desktop/projects/my_jobs_env/lib/python3.6/site-packages/rest_framework/views.py", line 459, in handle_exception
    exception_handler = self.get_exception_handler()
  File "/home/rumi/Desktop/projects/my_jobs_env/lib/python3.6/site-packages/rest_framework/views.py", line 298, in get_exception_handler
    return self.settings.EXCEPTION_HANDLER
  File "/home/rumi/Desktop/projects/my_jobs_env/lib/python3.6/site-packages/rest_framework/settings.py", line 220, in __getattr__
    val = perform_import(val, attr)
  File "/home/rumi/Desktop/projects/my_jobs_env/lib/python3.6/site-packages/rest_framework/settings.py", line 166, in perform_import
    return import_from_string(val, setting_name)
  File "/home/rumi/Desktop/projects/my_jobs_env/lib/python3.6/site-packages/rest_framework/settings.py", line 180, in import_from_string
    raise ImportError(msg)
ImportError: Could not import 'core.api.custom_exception.custom_exception_handler' for API setting 'EXCEPTION_HANDLER'. ModuleNotFoundError: No module named 'core'.
"GET /api/jobs/ HTTP/1.1" 500 155460
"GET /api/jobs/ HTTP/1.1" 500 155460
/home/rumi/Desktop/projects/my_jobs_env/django-job-portal/jobs/wsgi.py changed, reloading.
/home/rumi/Desktop/projects/my_jobs_env/django-job-portal/jobs/wsgi.py changed, reloading.
Watching for file changes with StatReloader
Watching for file changes with StatReloader
/home/rumi/Desktop/projects/my_jobs_env/django-job-portal/jobs/settings.py changed, reloading.
/home/rumi/Desktop/projects/my_jobs_env/django-job-portal/jobs/settings.py changed, reloading.
Watching for file changes with StatReloader
Watching for file changes with StatReloader
Watching for file changes with StatReloader
Watching for file changes with StatReloader
Internal Server Error: /api/jobs/
Traceback (most recent call last):
  File "/home/rumi/Desktop/projects/my_jobs_env/lib/python3.6/site-packages/rest_framework/views.py", line 493, in dispatch
    self.initial(request, *args, **kwargs)
  File "/home/rumi/Desktop/projects/my_jobs_env/lib/python3.6/site-packages/rest_framework/views.py", line 411, in initial
    self.check_permissions(request)
  File "/home/rumi/Desktop/projects/my_jobs_env/lib/python3.6/site-packages/rest_framework/views.py", line 334, in check_permissions
    request, message=getattr(permission, 'message', None)
  File "/home/rumi/Desktop/projects/my_jobs_env/lib/python3.6/site-packages/rest_framework/views.py", line 174, in permission_denied
    raise exceptions.NotAuthenticated()
rest_framework.exceptions.NotAuthenticated: Authentication credentials were not provided.

During handling of the above exception, another exception occurred:

Traceback (most recent call last):
  File "/home/rumi/Desktop/projects/my_jobs_env/lib/python3.6/site-packages/rest_framework/settings.py", line 177, in import_from_string
    return import_string(val)
  File "/home/rumi/Desktop/projects/my_jobs_env/lib/python3.6/site-packages/django/utils/module_loading.py", line 17, in import_string
    module = import_module(module_path)
  File "/home/rumi/Desktop/projects/my_jobs_env/lib/python3.6/importlib/__init__.py", line 126, in import_module
    return _bootstrap._gcd_import(name[level:], package, level)
  File "<frozen importlib._bootstrap>", line 994, in _gcd_import
  File "<frozen importlib._bootstrap>", line 971, in _find_and_load
  File "<frozen importlib._bootstrap>", line 941, in _find_and_load_unlocked
  File "<frozen importlib._bootstrap>", line 219, in _call_with_frames_removed
  File "<frozen importlib._bootstrap>", line 994, in _gcd_import
  File "<frozen importlib._bootstrap>", line 971, in _find_and_load
  File "<frozen importlib._bootstrap>", line 941, in _find_and_load_unlocked
  File "<frozen importlib._bootstrap>", line 219, in _call_with_frames_removed
  File "<frozen importlib._bootstrap>", line 994, in _gcd_import
  File "<frozen importlib._bootstrap>", line 971, in _find_and_load
  File "<frozen importlib._bootstrap>", line 953, in _find_and_load_unlocked
ModuleNotFoundError: No module named 'core'

During handling of the above exception, another exception occurred:

Traceback (most recent call last):
  File "/home/rumi/Desktop/projects/my_jobs_env/lib/python3.6/site-packages/django/core/handlers/exception.py", line 34, in inner
    response = get_response(request)
  File "/home/rumi/Desktop/projects/my_jobs_env/lib/python3.6/site-packages/django/core/handlers/base.py", line 115, in _get_response
    response = self.process_exception_by_middleware(e, request)
  File "/home/rumi/Desktop/projects/my_jobs_env/lib/python3.6/site-packages/django/core/handlers/base.py", line 113, in _get_response
    response = wrapped_callback(request, *callback_args, **callback_kwargs)
  File "/home/rumi/Desktop/projects/my_jobs_env/lib/python3.6/site-packages/django/views/decorators/csrf.py", line 54, in wrapped_view
    return view_func(*args, **kwargs)
  File "/home/rumi/Desktop/projects/my_jobs_env/lib/python3.6/site-packages/rest_framework/viewsets.py", line 114, in view
    return self.dispatch(request, *args, **kwargs)
  File "/home/rumi/Desktop/projects/my_jobs_env/lib/python3.6/site-packages/rest_framework/views.py", line 505, in dispatch
    response = self.handle_exception(exc)
  File "/home/rumi/Desktop/projects/my_jobs_env/lib/python3.6/site-packages/rest_framework/views.py", line 459, in handle_exception
    exception_handler = self.get_exception_handler()
  File "/home/rumi/Desktop/projects/my_jobs_env/lib/python3.6/site-packages/rest_framework/views.py", line 298, in get_exception_handler
    return self.settings.EXCEPTION_HANDLER
  File "/home/rumi/Desktop/projects/my_jobs_env/lib/python3.6/site-packages/rest_framework/settings.py", line 220, in __getattr__
    val = perform_import(val, attr)
  File "/home/rumi/Desktop/projects/my_jobs_env/lib/python3.6/site-packages/rest_framework/settings.py", line 166, in perform_import
    return import_from_string(val, setting_name)
  File "/home/rumi/Desktop/projects/my_jobs_env/lib/python3.6/site-packages/rest_framework/settings.py", line 180, in import_from_string
    raise ImportError(msg)
ImportError: Could not import 'core.api.custom_exception.custom_exception_handler' for API setting 'EXCEPTION_HANDLER'. ModuleNotFoundError: No module named 'core'.
Internal Server Error: /api/jobs/
Traceback (most recent call last):
  File "/home/rumi/Desktop/projects/my_jobs_env/lib/python3.6/site-packages/rest_framework/views.py", line 493, in dispatch
    self.initial(request, *args, **kwargs)
  File "/home/rumi/Desktop/projects/my_jobs_env/lib/python3.6/site-packages/rest_framework/views.py", line 411, in initial
    self.check_permissions(request)
  File "/home/rumi/Desktop/projects/my_jobs_env/lib/python3.6/site-packages/rest_framework/views.py", line 334, in check_permissions
    request, message=getattr(permission, 'message', None)
  File "/home/rumi/Desktop/projects/my_jobs_env/lib/python3.6/site-packages/rest_framework/views.py", line 174, in permission_denied
    raise exceptions.NotAuthenticated()
rest_framework.exceptions.NotAuthenticated: Authentication credentials were not provided.

During handling of the above exception, another exception occurred:

Traceback (most recent call last):
  File "/home/rumi/Desktop/projects/my_jobs_env/lib/python3.6/site-packages/rest_framework/settings.py", line 177, in import_from_string
    return import_string(val)
  File "/home/rumi/Desktop/projects/my_jobs_env/lib/python3.6/site-packages/django/utils/module_loading.py", line 17, in import_string
    module = import_module(module_path)
  File "/home/rumi/Desktop/projects/my_jobs_env/lib/python3.6/importlib/__init__.py", line 126, in import_module
    return _bootstrap._gcd_import(name[level:], package, level)
  File "<frozen importlib._bootstrap>", line 994, in _gcd_import
  File "<frozen importlib._bootstrap>", line 971, in _find_and_load
  File "<frozen importlib._bootstrap>", line 941, in _find_and_load_unlocked
  File "<frozen importlib._bootstrap>", line 219, in _call_with_frames_removed
  File "<frozen importlib._bootstrap>", line 994, in _gcd_import
  File "<frozen importlib._bootstrap>", line 971, in _find_and_load
  File "<frozen importlib._bootstrap>", line 941, in _find_and_load_unlocked
  File "<frozen importlib._bootstrap>", line 219, in _call_with_frames_removed
  File "<frozen importlib._bootstrap>", line 994, in _gcd_import
  File "<frozen importlib._bootstrap>", line 971, in _find_and_load
  File "<frozen importlib._bootstrap>", line 953, in _find_and_load_unlocked
ModuleNotFoundError: No module named 'core'

During handling of the above exception, another exception occurred:

Traceback (most recent call last):
  File "/home/rumi/Desktop/projects/my_jobs_env/lib/python3.6/site-packages/django/core/handlers/exception.py", line 34, in inner
    response = get_response(request)
  File "/home/rumi/Desktop/projects/my_jobs_env/lib/python3.6/site-packages/django/core/handlers/base.py", line 115, in _get_response
    response = self.process_exception_by_middleware(e, request)
  File "/home/rumi/Desktop/projects/my_jobs_env/lib/python3.6/site-packages/django/core/handlers/base.py", line 113, in _get_response
    response = wrapped_callback(request, *callback_args, **callback_kwargs)
  File "/home/rumi/Desktop/projects/my_jobs_env/lib/python3.6/site-packages/django/views/decorators/csrf.py", line 54, in wrapped_view
    return view_func(*args, **kwargs)
  File "/home/rumi/Desktop/projects/my_jobs_env/lib/python3.6/site-packages/rest_framework/viewsets.py", line 114, in view
    return self.dispatch(request, *args, **kwargs)
  File "/home/rumi/Desktop/projects/my_jobs_env/lib/python3.6/site-packages/rest_framework/views.py", line 505, in dispatch
    response = self.handle_exception(exc)
  File "/home/rumi/Desktop/projects/my_jobs_env/lib/python3.6/site-packages/rest_framework/views.py", line 459, in handle_exception
    exception_handler = self.get_exception_handler()
  File "/home/rumi/Desktop/projects/my_jobs_env/lib/python3.6/site-packages/rest_framework/views.py", line 298, in get_exception_handler
    return self.settings.EXCEPTION_HANDLER
  File "/home/rumi/Desktop/projects/my_jobs_env/lib/python3.6/site-packages/rest_framework/settings.py", line 220, in __getattr__
    val = perform_import(val, attr)
  File "/home/rumi/Desktop/projects/my_jobs_env/lib/python3.6/site-packages/rest_framework/settings.py", line 166, in perform_import
    return import_from_string(val, setting_name)
  File "/home/rumi/Desktop/projects/my_jobs_env/lib/python3.6/site-packages/rest_framework/settings.py", line 180, in import_from_string
    raise ImportError(msg)
ImportError: Could not import 'core.api.custom_exception.custom_exception_handler' for API setting 'EXCEPTION_HANDLER'. ModuleNotFoundError: No module named 'core'.
"GET /api/jobs/ HTTP/1.1" 500 155460
"GET /api/jobs/ HTTP/1.1" 500 155460
/home/rumi/Desktop/projects/my_jobs_env/django-job-portal/jobs/settings.py changed, reloading.
/home/rumi/Desktop/projects/my_jobs_env/django-job-portal/jobs/settings.py changed, reloading.
Watching for file changes with StatReloader
Watching for file changes with StatReloader
Unauthorized: /api/jobs/
Unauthorized: /api/jobs/
"GET /api/jobs/ HTTP/1.1" 401 142
"GET /api/jobs/ HTTP/1.1" 401 142
/home/rumi/Desktop/projects/my_jobs_env/django-job-portal/jobsapp/api/custom_exception.py changed, reloading.
/home/rumi/Desktop/projects/my_jobs_env/django-job-portal/jobsapp/api/custom_exception.py changed, reloading.
Watching for file changes with StatReloader
Watching for file changes with StatReloader
Unauthorized: /api/jobs/
Unauthorized: /api/jobs/
"GET /api/jobs/ HTTP/1.1" 401 141
"GET /api/jobs/ HTTP/1.1" 401 141
/home/rumi/Desktop/projects/my_jobs_env/django-job-portal/jobs/settings.py changed, reloading.
/home/rumi/Desktop/projects/my_jobs_env/django-job-portal/jobs/settings.py changed, reloading.
Watching for file changes with StatReloader
Watching for file changes with StatReloader
/home/rumi/Desktop/projects/my_jobs_env/django-job-portal/jobsapp/api/views.py changed, reloading.
/home/rumi/Desktop/projects/my_jobs_env/django-job-portal/jobsapp/api/views.py changed, reloading.
Watching for file changes with StatReloader
Watching for file changes with StatReloader
/home/rumi/Desktop/projects/my_jobs_env/django-job-portal/jobsapp/api/views.py changed, reloading.
/home/rumi/Desktop/projects/my_jobs_env/django-job-portal/jobsapp/api/views.py changed, reloading.
Watching for file changes with StatReloader
Watching for file changes with StatReloader
"GET /api/jobs/ HTTP/1.1" 200 6683
"GET /api/jobs/ HTTP/1.1" 200 6683
/home/rumi/Desktop/projects/my_jobs_env/django-job-portal/jobsapp/api/views.py changed, reloading.
/home/rumi/Desktop/projects/my_jobs_env/django-job-portal/jobsapp/api/views.py changed, reloading.
Watching for file changes with StatReloader
Watching for file changes with StatReloader
"GET /employee/register HTTP/1.1" 200 9327
"GET /employee/register HTTP/1.1" 200 9327
Not Found: /employee/favicon.png
Not Found: /employee/favicon.png
"GET /employee/favicon.png HTTP/1.1" 404 4423
"GET /employee/favicon.png HTTP/1.1" 404 4423
"GET /login HTTP/1.1" 200 6545
"GET /login HTTP/1.1" 200 6545
"POST /api/login/ HTTP/1.1" 200 873
"POST /api/login/ HTTP/1.1" 200 873
Unauthorized: /api/login/
Unauthorized: /api/login/
"POST /api/login/ HTTP/1.1" 401 151
"POST /api/login/ HTTP/1.1" 401 151
"POST /api/login/ HTTP/1.1" 200 873
"POST /api/login/ HTTP/1.1" 200 873
/home/rumi/Desktop/projects/my_jobs_env/django-job-portal/accounts/api/serializers.py changed, reloading.
/home/rumi/Desktop/projects/my_jobs_env/django-job-portal/accounts/api/serializers.py changed, reloading.
Watching for file changes with StatReloader
Watching for file changes with StatReloader
/home/rumi/Desktop/projects/my_jobs_env/django-job-portal/accounts/api/urls.py changed, reloading.
/home/rumi/Desktop/projects/my_jobs_env/django-job-portal/accounts/api/urls.py changed, reloading.
Watching for file changes with StatReloader
Watching for file changes with StatReloader
Bad Request: /api/register/
Bad Request: /api/register/
"POST /api/register/ HTTP/1.1" 400 52
"POST /api/register/ HTTP/1.1" 400 52
/home/rumi/Desktop/projects/my_jobs_env/django-job-portal/accounts/api/views.py changed, reloading.
/home/rumi/Desktop/projects/my_jobs_env/django-job-portal/accounts/api/views.py changed, reloading.
Watching for file changes with StatReloader
Watching for file changes with StatReloader
Bad Request: /api/register/
Bad Request: /api/register/
"POST /api/register/ HTTP/1.1" 400 215
"POST /api/register/ HTTP/1.1" 400 215
/home/rumi/Desktop/projects/my_jobs_env/django-job-portal/accounts/api/views.py changed, reloading.
/home/rumi/Desktop/projects/my_jobs_env/django-job-portal/accounts/api/views.py changed, reloading.
Watching for file changes with StatReloader
Watching for file changes with StatReloader
Bad Request: /api/register/
Bad Request: /api/register/
"POST /api/register/ HTTP/1.1" 400 52
"POST /api/register/ HTTP/1.1" 400 52
/home/rumi/Desktop/projects/my_jobs_env/django-job-portal/accounts/api/views.py changed, reloading.
/home/rumi/Desktop/projects/my_jobs_env/django-job-portal/accounts/api/views.py changed, reloading.
Watching for file changes with StatReloader
Watching for file changes with StatReloader
Bad Request: /api/register/
Bad Request: /api/register/
"POST /api/register/ HTTP/1.1" 400 215
"POST /api/register/ HTTP/1.1" 400 215
/home/rumi/Desktop/projects/my_jobs_env/django-job-portal/jobsapp/api/custom_exception.py changed, reloading.
/home/rumi/Desktop/projects/my_jobs_env/django-job-portal/jobsapp/api/custom_exception.py changed, reloading.
Watching for file changes with StatReloader
Watching for file changes with StatReloader
Bad Request: /api/register/
Bad Request: /api/register/
"POST /api/register/ HTTP/1.1" 400 215
"POST /api/register/ HTTP/1.1" 400 215
/home/rumi/Desktop/projects/my_jobs_env/django-job-portal/jobsapp/api/custom_exception.py changed, reloading.
/home/rumi/Desktop/projects/my_jobs_env/django-job-portal/jobsapp/api/custom_exception.py changed, reloading.
Watching for file changes with StatReloader
Watching for file changes with StatReloader
Bad Request: /api/register/
Bad Request: /api/register/
"POST /api/register/ HTTP/1.1" 400 215
"POST /api/register/ HTTP/1.1" 400 215
/home/rumi/Desktop/projects/my_jobs_env/django-job-portal/jobsapp/api/custom_exception.py changed, reloading.
/home/rumi/Desktop/projects/my_jobs_env/django-job-portal/jobsapp/api/custom_exception.py changed, reloading.
Watching for file changes with StatReloader
Watching for file changes with StatReloader
Bad Request: /api/register/
Bad Request: /api/register/
"POST /api/register/ HTTP/1.1" 400 215
"POST /api/register/ HTTP/1.1" 400 215
/home/rumi/Desktop/projects/my_jobs_env/django-job-portal/jobsapp/api/custom_exception.py changed, reloading.
/home/rumi/Desktop/projects/my_jobs_env/django-job-portal/jobsapp/api/custom_exception.py changed, reloading.
Watching for file changes with StatReloader
Watching for file changes with StatReloader
/home/rumi/Desktop/projects/my_jobs_env/django-job-portal/accounts/api/serializers.py changed, reloading.
/home/rumi/Desktop/projects/my_jobs_env/django-job-portal/accounts/api/serializers.py changed, reloading.
Watching for file changes with StatReloader
Watching for file changes with StatReloader
Bad Request: /api/register/
Bad Request: /api/register/
"POST /api/register/ HTTP/1.1" 400 215
"POST /api/register/ HTTP/1.1" 400 215
/home/rumi/Desktop/projects/my_jobs_env/django-job-portal/jobsapp/api/custom_exception.py changed, reloading.
/home/rumi/Desktop/projects/my_jobs_env/django-job-portal/jobsapp/api/custom_exception.py changed, reloading.
Watching for file changes with StatReloader
Watching for file changes with StatReloader
Bad Request: /api/register/
Bad Request: /api/register/
"POST /api/register/ HTTP/1.1" 400 215
"POST /api/register/ HTTP/1.1" 400 215
Bad Request: /api/register/
Bad Request: /api/register/
"POST /api/register/ HTTP/1.1" 400 215
"POST /api/register/ HTTP/1.1" 400 215
Bad Request: /api/register/
Bad Request: /api/register/
"POST /api/register/ HTTP/1.1" 400 215
"POST /api/register/ HTTP/1.1" 400 215
/home/rumi/Desktop/projects/my_jobs_env/django-job-portal/jobsapp/api/custom_exception.py changed, reloading.
/home/rumi/Desktop/projects/my_jobs_env/django-job-portal/jobsapp/api/custom_exception.py changed, reloading.
Watching for file changes with StatReloader
Watching for file changes with StatReloader
Bad Request: /api/register/
Bad Request: /api/register/
"POST /api/register/ HTTP/1.1" 400 176
"POST /api/register/ HTTP/1.1" 400 176
/home/rumi/Desktop/projects/my_jobs_env/django-job-portal/jobsapp/api/custom_exception.py changed, reloading.
/home/rumi/Desktop/projects/my_jobs_env/django-job-portal/jobsapp/api/custom_exception.py changed, reloading.
Watching for file changes with StatReloader
Watching for file changes with StatReloader
Bad Request: /api/register/
Bad Request: /api/register/
"POST /api/register/ HTTP/1.1" 400 176
"POST /api/register/ HTTP/1.1" 400 176
/home/rumi/Desktop/projects/my_jobs_env/django-job-portal/jobsapp/api/custom_exception.py changed, reloading.
/home/rumi/Desktop/projects/my_jobs_env/django-job-portal/jobsapp/api/custom_exception.py changed, reloading.
Watching for file changes with StatReloader
Watching for file changes with StatReloader
Bad Request: /api/register/
Bad Request: /api/register/
"POST /api/register/ HTTP/1.1" 400 176
"POST /api/register/ HTTP/1.1" 400 176
/home/rumi/Desktop/projects/my_jobs_env/django-job-portal/jobsapp/api/custom_exception.py changed, reloading.
/home/rumi/Desktop/projects/my_jobs_env/django-job-portal/jobsapp/api/custom_exception.py changed, reloading.
Watching for file changes with StatReloader
Watching for file changes with StatReloader
Internal Server Error: /api/register/
Traceback (most recent call last):
  File "/home/rumi/Desktop/projects/my_jobs_env/lib/python3.6/site-packages/rest_framework/views.py", line 502, in dispatch
    response = handler(request, *args, **kwargs)
  File "/home/rumi/Desktop/projects/my_jobs_env/lib/python3.6/site-packages/rest_framework/decorators.py", line 50, in handler
    return func(*args, **kwargs)
  File "/home/rumi/Desktop/projects/my_jobs_env/django-job-portal/accounts/api/views.py", line 13, in registration
    if not serializer.is_valid(raise_exception=True):
  File "/home/rumi/Desktop/projects/my_jobs_env/lib/python3.6/site-packages/rest_framework/serializers.py", line 242, in is_valid
    raise ValidationError(self.errors)
rest_framework.exceptions.ValidationError: {'email': [ErrorDetail(string='A user with that email already exists.', code='unique')]}

During handling of the above exception, another exception occurred:

Traceback (most recent call last):
  File "/home/rumi/Desktop/projects/my_jobs_env/lib/python3.6/site-packages/django/core/handlers/exception.py", line 34, in inner
    response = get_response(request)
  File "/home/rumi/Desktop/projects/my_jobs_env/lib/python3.6/site-packages/django/core/handlers/base.py", line 115, in _get_response
    response = self.process_exception_by_middleware(e, request)
  File "/home/rumi/Desktop/projects/my_jobs_env/lib/python3.6/site-packages/django/core/handlers/base.py", line 113, in _get_response
    response = wrapped_callback(request, *callback_args, **callback_kwargs)
  File "/home/rumi/Desktop/projects/my_jobs_env/lib/python3.6/site-packages/django/views/decorators/csrf.py", line 54, in wrapped_view
    return view_func(*args, **kwargs)
  File "/home/rumi/Desktop/projects/my_jobs_env/lib/python3.6/site-packages/django/views/generic/base.py", line 71, in view
    return self.dispatch(request, *args, **kwargs)
  File "/home/rumi/Desktop/projects/my_jobs_env/lib/python3.6/site-packages/rest_framework/views.py", line 505, in dispatch
    response = self.handle_exception(exc)
  File "/home/rumi/Desktop/projects/my_jobs_env/lib/python3.6/site-packages/rest_framework/views.py", line 462, in handle_exception
    response = exception_handler(exc, context)
  File "/home/rumi/Desktop/projects/my_jobs_env/django-job-portal/jobsapp/api/custom_exception.py", line 28, in custom_exception_handler
    for value in exc.values():
AttributeError: 'ValidationError' object has no attribute 'values'
Internal Server Error: /api/register/
Traceback (most recent call last):
  File "/home/rumi/Desktop/projects/my_jobs_env/lib/python3.6/site-packages/rest_framework/views.py", line 502, in dispatch
    response = handler(request, *args, **kwargs)
  File "/home/rumi/Desktop/projects/my_jobs_env/lib/python3.6/site-packages/rest_framework/decorators.py", line 50, in handler
    return func(*args, **kwargs)
  File "/home/rumi/Desktop/projects/my_jobs_env/django-job-portal/accounts/api/views.py", line 13, in registration
    if not serializer.is_valid(raise_exception=True):
  File "/home/rumi/Desktop/projects/my_jobs_env/lib/python3.6/site-packages/rest_framework/serializers.py", line 242, in is_valid
    raise ValidationError(self.errors)
rest_framework.exceptions.ValidationError: {'email': [ErrorDetail(string='A user with that email already exists.', code='unique')]}

During handling of the above exception, another exception occurred:

Traceback (most recent call last):
  File "/home/rumi/Desktop/projects/my_jobs_env/lib/python3.6/site-packages/django/core/handlers/exception.py", line 34, in inner
    response = get_response(request)
  File "/home/rumi/Desktop/projects/my_jobs_env/lib/python3.6/site-packages/django/core/handlers/base.py", line 115, in _get_response
    response = self.process_exception_by_middleware(e, request)
  File "/home/rumi/Desktop/projects/my_jobs_env/lib/python3.6/site-packages/django/core/handlers/base.py", line 113, in _get_response
    response = wrapped_callback(request, *callback_args, **callback_kwargs)
  File "/home/rumi/Desktop/projects/my_jobs_env/lib/python3.6/site-packages/django/views/decorators/csrf.py", line 54, in wrapped_view
    return view_func(*args, **kwargs)
  File "/home/rumi/Desktop/projects/my_jobs_env/lib/python3.6/site-packages/django/views/generic/base.py", line 71, in view
    return self.dispatch(request, *args, **kwargs)
  File "/home/rumi/Desktop/projects/my_jobs_env/lib/python3.6/site-packages/rest_framework/views.py", line 505, in dispatch
    response = self.handle_exception(exc)
  File "/home/rumi/Desktop/projects/my_jobs_env/lib/python3.6/site-packages/rest_framework/views.py", line 462, in handle_exception
    response = exception_handler(exc, context)
  File "/home/rumi/Desktop/projects/my_jobs_env/django-job-portal/jobsapp/api/custom_exception.py", line 28, in custom_exception_handler
    for value in exc.values():
AttributeError: 'ValidationError' object has no attribute 'values'
"POST /api/register/ HTTP/1.1" 500 113070
"POST /api/register/ HTTP/1.1" 500 113070
/home/rumi/Desktop/projects/my_jobs_env/django-job-portal/jobsapp/api/custom_exception.py changed, reloading.
/home/rumi/Desktop/projects/my_jobs_env/django-job-portal/jobsapp/api/custom_exception.py changed, reloading.
Watching for file changes with StatReloader
Watching for file changes with StatReloader
Internal Server Error: /api/register/
Traceback (most recent call last):
  File "/home/rumi/Desktop/projects/my_jobs_env/lib/python3.6/site-packages/rest_framework/views.py", line 502, in dispatch
    response = handler(request, *args, **kwargs)
  File "/home/rumi/Desktop/projects/my_jobs_env/lib/python3.6/site-packages/rest_framework/decorators.py", line 50, in handler
    return func(*args, **kwargs)
  File "/home/rumi/Desktop/projects/my_jobs_env/django-job-portal/accounts/api/views.py", line 13, in registration
    if not serializer.is_valid(raise_exception=True):
  File "/home/rumi/Desktop/projects/my_jobs_env/lib/python3.6/site-packages/rest_framework/serializers.py", line 242, in is_valid
    raise ValidationError(self.errors)
rest_framework.exceptions.ValidationError: {'email': [ErrorDetail(string='A user with that email already exists.', code='unique')]}

During handling of the above exception, another exception occurred:

Traceback (most recent call last):
  File "/home/rumi/Desktop/projects/my_jobs_env/lib/python3.6/site-packages/django/core/handlers/exception.py", line 34, in inner
    response = get_response(request)
  File "/home/rumi/Desktop/projects/my_jobs_env/lib/python3.6/site-packages/django/core/handlers/base.py", line 115, in _get_response
    response = self.process_exception_by_middleware(e, request)
  File "/home/rumi/Desktop/projects/my_jobs_env/lib/python3.6/site-packages/django/core/handlers/base.py", line 113, in _get_response
    response = wrapped_callback(request, *callback_args, **callback_kwargs)
  File "/home/rumi/Desktop/projects/my_jobs_env/lib/python3.6/site-packages/django/views/decorators/csrf.py", line 54, in wrapped_view
    return view_func(*args, **kwargs)
  File "/home/rumi/Desktop/projects/my_jobs_env/lib/python3.6/site-packages/django/views/generic/base.py", line 71, in view
    return self.dispatch(request, *args, **kwargs)
  File "/home/rumi/Desktop/projects/my_jobs_env/lib/python3.6/site-packages/rest_framework/views.py", line 505, in dispatch
    response = self.handle_exception(exc)
  File "/home/rumi/Desktop/projects/my_jobs_env/lib/python3.6/site-packages/rest_framework/views.py", line 462, in handle_exception
    response = exception_handler(exc, context)
  File "/home/rumi/Desktop/projects/my_jobs_env/django-job-portal/jobsapp/api/custom_exception.py", line 28, in custom_exception_handler
    for value in exc:
TypeError: 'ValidationError' object is not iterable
Internal Server Error: /api/register/
Traceback (most recent call last):
  File "/home/rumi/Desktop/projects/my_jobs_env/lib/python3.6/site-packages/rest_framework/views.py", line 502, in dispatch
    response = handler(request, *args, **kwargs)
  File "/home/rumi/Desktop/projects/my_jobs_env/lib/python3.6/site-packages/rest_framework/decorators.py", line 50, in handler
    return func(*args, **kwargs)
  File "/home/rumi/Desktop/projects/my_jobs_env/django-job-portal/accounts/api/views.py", line 13, in registration
    if not serializer.is_valid(raise_exception=True):
  File "/home/rumi/Desktop/projects/my_jobs_env/lib/python3.6/site-packages/rest_framework/serializers.py", line 242, in is_valid
    raise ValidationError(self.errors)
rest_framework.exceptions.ValidationError: {'email': [ErrorDetail(string='A user with that email already exists.', code='unique')]}

During handling of the above exception, another exception occurred:

Traceback (most recent call last):
  File "/home/rumi/Desktop/projects/my_jobs_env/lib/python3.6/site-packages/django/core/handlers/exception.py", line 34, in inner
    response = get_response(request)
  File "/home/rumi/Desktop/projects/my_jobs_env/lib/python3.6/site-packages/django/core/handlers/base.py", line 115, in _get_response
    response = self.process_exception_by_middleware(e, request)
  File "/home/rumi/Desktop/projects/my_jobs_env/lib/python3.6/site-packages/django/core/handlers/base.py", line 113, in _get_response
    response = wrapped_callback(request, *callback_args, **callback_kwargs)
  File "/home/rumi/Desktop/projects/my_jobs_env/lib/python3.6/site-packages/django/views/decorators/csrf.py", line 54, in wrapped_view
    return view_func(*args, **kwargs)
  File "/home/rumi/Desktop/projects/my_jobs_env/lib/python3.6/site-packages/django/views/generic/base.py", line 71, in view
    return self.dispatch(request, *args, **kwargs)
  File "/home/rumi/Desktop/projects/my_jobs_env/lib/python3.6/site-packages/rest_framework/views.py", line 505, in dispatch
    response = self.handle_exception(exc)
  File "/home/rumi/Desktop/projects/my_jobs_env/lib/python3.6/site-packages/rest_framework/views.py", line 462, in handle_exception
    response = exception_handler(exc, context)
  File "/home/rumi/Desktop/projects/my_jobs_env/django-job-portal/jobsapp/api/custom_exception.py", line 28, in custom_exception_handler
    for value in exc:
TypeError: 'ValidationError' object is not iterable
"POST /api/register/ HTTP/1.1" 500 112942
"POST /api/register/ HTTP/1.1" 500 112942
/home/rumi/Desktop/projects/my_jobs_env/django-job-portal/jobsapp/api/custom_exception.py changed, reloading.
/home/rumi/Desktop/projects/my_jobs_env/django-job-portal/jobsapp/api/custom_exception.py changed, reloading.
Watching for file changes with StatReloader
Watching for file changes with StatReloader
Internal Server Error: /api/register/
Traceback (most recent call last):
  File "/home/rumi/Desktop/projects/my_jobs_env/lib/python3.6/site-packages/rest_framework/views.py", line 502, in dispatch
    response = handler(request, *args, **kwargs)
  File "/home/rumi/Desktop/projects/my_jobs_env/lib/python3.6/site-packages/rest_framework/decorators.py", line 50, in handler
    return func(*args, **kwargs)
  File "/home/rumi/Desktop/projects/my_jobs_env/django-job-portal/accounts/api/views.py", line 13, in registration
    if not serializer.is_valid(raise_exception=True):
  File "/home/rumi/Desktop/projects/my_jobs_env/lib/python3.6/site-packages/rest_framework/serializers.py", line 242, in is_valid
    raise ValidationError(self.errors)
rest_framework.exceptions.ValidationError: {'email': [ErrorDetail(string='A user with that email already exists.', code='unique')]}

During handling of the above exception, another exception occurred:

Traceback (most recent call last):
  File "/home/rumi/Desktop/projects/my_jobs_env/lib/python3.6/site-packages/django/core/handlers/exception.py", line 34, in inner
    response = get_response(request)
  File "/home/rumi/Desktop/projects/my_jobs_env/lib/python3.6/site-packages/django/core/handlers/base.py", line 115, in _get_response
    response = self.process_exception_by_middleware(e, request)
  File "/home/rumi/Desktop/projects/my_jobs_env/lib/python3.6/site-packages/django/core/handlers/base.py", line 113, in _get_response
    response = wrapped_callback(request, *callback_args, **callback_kwargs)
  File "/home/rumi/Desktop/projects/my_jobs_env/lib/python3.6/site-packages/django/views/decorators/csrf.py", line 54, in wrapped_view
    return view_func(*args, **kwargs)
  File "/home/rumi/Desktop/projects/my_jobs_env/lib/python3.6/site-packages/django/views/generic/base.py", line 71, in view
    return self.dispatch(request, *args, **kwargs)
  File "/home/rumi/Desktop/projects/my_jobs_env/lib/python3.6/site-packages/rest_framework/views.py", line 505, in dispatch
    response = self.handle_exception(exc)
  File "/home/rumi/Desktop/projects/my_jobs_env/lib/python3.6/site-packages/rest_framework/views.py", line 462, in handle_exception
    response = exception_handler(exc, context)
  File "/home/rumi/Desktop/projects/my_jobs_env/django-job-portal/jobsapp/api/custom_exception.py", line 28, in custom_exception_handler
    for value in dict(exc).values():
TypeError: 'ValidationError' object is not iterable
Internal Server Error: /api/register/
Traceback (most recent call last):
  File "/home/rumi/Desktop/projects/my_jobs_env/lib/python3.6/site-packages/rest_framework/views.py", line 502, in dispatch
    response = handler(request, *args, **kwargs)
  File "/home/rumi/Desktop/projects/my_jobs_env/lib/python3.6/site-packages/rest_framework/decorators.py", line 50, in handler
    return func(*args, **kwargs)
  File "/home/rumi/Desktop/projects/my_jobs_env/django-job-portal/accounts/api/views.py", line 13, in registration
    if not serializer.is_valid(raise_exception=True):
  File "/home/rumi/Desktop/projects/my_jobs_env/lib/python3.6/site-packages/rest_framework/serializers.py", line 242, in is_valid
    raise ValidationError(self.errors)
rest_framework.exceptions.ValidationError: {'email': [ErrorDetail(string='A user with that email already exists.', code='unique')]}

During handling of the above exception, another exception occurred:

Traceback (most recent call last):
  File "/home/rumi/Desktop/projects/my_jobs_env/lib/python3.6/site-packages/django/core/handlers/exception.py", line 34, in inner
    response = get_response(request)
  File "/home/rumi/Desktop/projects/my_jobs_env/lib/python3.6/site-packages/django/core/handlers/base.py", line 115, in _get_response
    response = self.process_exception_by_middleware(e, request)
  File "/home/rumi/Desktop/projects/my_jobs_env/lib/python3.6/site-packages/django/core/handlers/base.py", line 113, in _get_response
    response = wrapped_callback(request, *callback_args, **callback_kwargs)
  File "/home/rumi/Desktop/projects/my_jobs_env/lib/python3.6/site-packages/django/views/decorators/csrf.py", line 54, in wrapped_view
    return view_func(*args, **kwargs)
  File "/home/rumi/Desktop/projects/my_jobs_env/lib/python3.6/site-packages/django/views/generic/base.py", line 71, in view
    return self.dispatch(request, *args, **kwargs)
  File "/home/rumi/Desktop/projects/my_jobs_env/lib/python3.6/site-packages/rest_framework/views.py", line 505, in dispatch
    response = self.handle_exception(exc)
  File "/home/rumi/Desktop/projects/my_jobs_env/lib/python3.6/site-packages/rest_framework/views.py", line 462, in handle_exception
    response = exception_handler(exc, context)
  File "/home/rumi/Desktop/projects/my_jobs_env/django-job-portal/jobsapp/api/custom_exception.py", line 28, in custom_exception_handler
    for value in dict(exc).values():
TypeError: 'ValidationError' object is not iterable
"POST /api/register/ HTTP/1.1" 500 112972
"POST /api/register/ HTTP/1.1" 500 112972
Internal Server Error: /api/register/
Traceback (most recent call last):
  File "/home/rumi/Desktop/projects/my_jobs_env/lib/python3.6/site-packages/rest_framework/views.py", line 502, in dispatch
    response = handler(request, *args, **kwargs)
  File "/home/rumi/Desktop/projects/my_jobs_env/lib/python3.6/site-packages/rest_framework/decorators.py", line 50, in handler
    return func(*args, **kwargs)
  File "/home/rumi/Desktop/projects/my_jobs_env/django-job-portal/accounts/api/views.py", line 13, in registration
    if not serializer.is_valid(raise_exception=True):
  File "/home/rumi/Desktop/projects/my_jobs_env/lib/python3.6/site-packages/rest_framework/serializers.py", line 242, in is_valid
    raise ValidationError(self.errors)
rest_framework.exceptions.ValidationError: {'email': [ErrorDetail(string='A user with that email already exists.', code='unique')]}

During handling of the above exception, another exception occurred:

Traceback (most recent call last):
  File "/home/rumi/Desktop/projects/my_jobs_env/lib/python3.6/site-packages/django/core/handlers/exception.py", line 34, in inner
    response = get_response(request)
  File "/home/rumi/Desktop/projects/my_jobs_env/lib/python3.6/site-packages/django/core/handlers/base.py", line 115, in _get_response
    response = self.process_exception_by_middleware(e, request)
  File "/home/rumi/Desktop/projects/my_jobs_env/lib/python3.6/site-packages/django/core/handlers/base.py", line 113, in _get_response
    response = wrapped_callback(request, *callback_args, **callback_kwargs)
  File "/home/rumi/Desktop/projects/my_jobs_env/lib/python3.6/site-packages/django/views/decorators/csrf.py", line 54, in wrapped_view
    return view_func(*args, **kwargs)
  File "/home/rumi/Desktop/projects/my_jobs_env/lib/python3.6/site-packages/django/views/generic/base.py", line 71, in view
    return self.dispatch(request, *args, **kwargs)
  File "/home/rumi/Desktop/projects/my_jobs_env/lib/python3.6/site-packages/rest_framework/views.py", line 505, in dispatch
    response = self.handle_exception(exc)
  File "/home/rumi/Desktop/projects/my_jobs_env/lib/python3.6/site-packages/rest_framework/views.py", line 462, in handle_exception
    response = exception_handler(exc, context)
  File "/home/rumi/Desktop/projects/my_jobs_env/django-job-portal/jobsapp/api/custom_exception.py", line 28, in custom_exception_handler
    for value in dict(exc).values():
TypeError: 'ValidationError' object is not iterable
Internal Server Error: /api/register/
Traceback (most recent call last):
  File "/home/rumi/Desktop/projects/my_jobs_env/lib/python3.6/site-packages/rest_framework/views.py", line 502, in dispatch
    response = handler(request, *args, **kwargs)
  File "/home/rumi/Desktop/projects/my_jobs_env/lib/python3.6/site-packages/rest_framework/decorators.py", line 50, in handler
    return func(*args, **kwargs)
  File "/home/rumi/Desktop/projects/my_jobs_env/django-job-portal/accounts/api/views.py", line 13, in registration
    if not serializer.is_valid(raise_exception=True):
  File "/home/rumi/Desktop/projects/my_jobs_env/lib/python3.6/site-packages/rest_framework/serializers.py", line 242, in is_valid
    raise ValidationError(self.errors)
rest_framework.exceptions.ValidationError: {'email': [ErrorDetail(string='A user with that email already exists.', code='unique')]}

During handling of the above exception, another exception occurred:

Traceback (most recent call last):
  File "/home/rumi/Desktop/projects/my_jobs_env/lib/python3.6/site-packages/django/core/handlers/exception.py", line 34, in inner
    response = get_response(request)
  File "/home/rumi/Desktop/projects/my_jobs_env/lib/python3.6/site-packages/django/core/handlers/base.py", line 115, in _get_response
    response = self.process_exception_by_middleware(e, request)
  File "/home/rumi/Desktop/projects/my_jobs_env/lib/python3.6/site-packages/django/core/handlers/base.py", line 113, in _get_response
    response = wrapped_callback(request, *callback_args, **callback_kwargs)
  File "/home/rumi/Desktop/projects/my_jobs_env/lib/python3.6/site-packages/django/views/decorators/csrf.py", line 54, in wrapped_view
    return view_func(*args, **kwargs)
  File "/home/rumi/Desktop/projects/my_jobs_env/lib/python3.6/site-packages/django/views/generic/base.py", line 71, in view
    return self.dispatch(request, *args, **kwargs)
  File "/home/rumi/Desktop/projects/my_jobs_env/lib/python3.6/site-packages/rest_framework/views.py", line 505, in dispatch
    response = self.handle_exception(exc)
  File "/home/rumi/Desktop/projects/my_jobs_env/lib/python3.6/site-packages/rest_framework/views.py", line 462, in handle_exception
    response = exception_handler(exc, context)
  File "/home/rumi/Desktop/projects/my_jobs_env/django-job-portal/jobsapp/api/custom_exception.py", line 28, in custom_exception_handler
    for value in dict(exc).values():
TypeError: 'ValidationError' object is not iterable
"POST /api/register/ HTTP/1.1" 500 112972
"POST /api/register/ HTTP/1.1" 500 112972
Internal Server Error: /api/register/
Traceback (most recent call last):
  File "/home/rumi/Desktop/projects/my_jobs_env/lib/python3.6/site-packages/rest_framework/views.py", line 502, in dispatch
    response = handler(request, *args, **kwargs)
  File "/home/rumi/Desktop/projects/my_jobs_env/lib/python3.6/site-packages/rest_framework/decorators.py", line 50, in handler
    return func(*args, **kwargs)
  File "/home/rumi/Desktop/projects/my_jobs_env/django-job-portal/accounts/api/views.py", line 13, in registration
    if not serializer.is_valid(raise_exception=True):
  File "/home/rumi/Desktop/projects/my_jobs_env/lib/python3.6/site-packages/rest_framework/serializers.py", line 242, in is_valid
    raise ValidationError(self.errors)
rest_framework.exceptions.ValidationError: {'email': [ErrorDetail(string='A user with that email already exists.', code='unique')]}

During handling of the above exception, another exception occurred:

Traceback (most recent call last):
  File "/home/rumi/Desktop/projects/my_jobs_env/lib/python3.6/site-packages/django/core/handlers/exception.py", line 34, in inner
    response = get_response(request)
  File "/home/rumi/Desktop/projects/my_jobs_env/lib/python3.6/site-packages/django/core/handlers/base.py", line 115, in _get_response
    response = self.process_exception_by_middleware(e, request)
  File "/home/rumi/Desktop/projects/my_jobs_env/lib/python3.6/site-packages/django/core/handlers/base.py", line 113, in _get_response
    response = wrapped_callback(request, *callback_args, **callback_kwargs)
  File "/home/rumi/Desktop/projects/my_jobs_env/lib/python3.6/site-packages/django/views/decorators/csrf.py", line 54, in wrapped_view
    return view_func(*args, **kwargs)
  File "/home/rumi/Desktop/projects/my_jobs_env/lib/python3.6/site-packages/django/views/generic/base.py", line 71, in view
    return self.dispatch(request, *args, **kwargs)
  File "/home/rumi/Desktop/projects/my_jobs_env/lib/python3.6/site-packages/rest_framework/views.py", line 505, in dispatch
    response = self.handle_exception(exc)
  File "/home/rumi/Desktop/projects/my_jobs_env/lib/python3.6/site-packages/rest_framework/views.py", line 462, in handle_exception
    response = exception_handler(exc, context)
  File "/home/rumi/Desktop/projects/my_jobs_env/django-job-portal/jobsapp/api/custom_exception.py", line 28, in custom_exception_handler
    for value in dict(exc).values():
TypeError: 'ValidationError' object is not iterable
Internal Server Error: /api/register/
Traceback (most recent call last):
  File "/home/rumi/Desktop/projects/my_jobs_env/lib/python3.6/site-packages/rest_framework/views.py", line 502, in dispatch
    response = handler(request, *args, **kwargs)
  File "/home/rumi/Desktop/projects/my_jobs_env/lib/python3.6/site-packages/rest_framework/decorators.py", line 50, in handler
    return func(*args, **kwargs)
  File "/home/rumi/Desktop/projects/my_jobs_env/django-job-portal/accounts/api/views.py", line 13, in registration
    if not serializer.is_valid(raise_exception=True):
  File "/home/rumi/Desktop/projects/my_jobs_env/lib/python3.6/site-packages/rest_framework/serializers.py", line 242, in is_valid
    raise ValidationError(self.errors)
rest_framework.exceptions.ValidationError: {'email': [ErrorDetail(string='A user with that email already exists.', code='unique')]}

During handling of the above exception, another exception occurred:

Traceback (most recent call last):
  File "/home/rumi/Desktop/projects/my_jobs_env/lib/python3.6/site-packages/django/core/handlers/exception.py", line 34, in inner
    response = get_response(request)
  File "/home/rumi/Desktop/projects/my_jobs_env/lib/python3.6/site-packages/django/core/handlers/base.py", line 115, in _get_response
    response = self.process_exception_by_middleware(e, request)
  File "/home/rumi/Desktop/projects/my_jobs_env/lib/python3.6/site-packages/django/core/handlers/base.py", line 113, in _get_response
    response = wrapped_callback(request, *callback_args, **callback_kwargs)
  File "/home/rumi/Desktop/projects/my_jobs_env/lib/python3.6/site-packages/django/views/decorators/csrf.py", line 54, in wrapped_view
    return view_func(*args, **kwargs)
  File "/home/rumi/Desktop/projects/my_jobs_env/lib/python3.6/site-packages/django/views/generic/base.py", line 71, in view
    return self.dispatch(request, *args, **kwargs)
  File "/home/rumi/Desktop/projects/my_jobs_env/lib/python3.6/site-packages/rest_framework/views.py", line 505, in dispatch
    response = self.handle_exception(exc)
  File "/home/rumi/Desktop/projects/my_jobs_env/lib/python3.6/site-packages/rest_framework/views.py", line 462, in handle_exception
    response = exception_handler(exc, context)
  File "/home/rumi/Desktop/projects/my_jobs_env/django-job-portal/jobsapp/api/custom_exception.py", line 28, in custom_exception_handler
    for value in dict(exc).values():
TypeError: 'ValidationError' object is not iterable
"POST /api/register/ HTTP/1.1" 500 112972
"POST /api/register/ HTTP/1.1" 500 112972
/home/rumi/Desktop/projects/my_jobs_env/django-job-portal/jobsapp/api/custom_exception.py changed, reloading.
/home/rumi/Desktop/projects/my_jobs_env/django-job-portal/jobsapp/api/custom_exception.py changed, reloading.
Watching for file changes with StatReloader
Watching for file changes with StatReloader
Internal Server Error: /api/register/
Traceback (most recent call last):
  File "/home/rumi/Desktop/projects/my_jobs_env/lib/python3.6/site-packages/rest_framework/views.py", line 502, in dispatch
    response = handler(request, *args, **kwargs)
  File "/home/rumi/Desktop/projects/my_jobs_env/lib/python3.6/site-packages/rest_framework/decorators.py", line 50, in handler
    return func(*args, **kwargs)
  File "/home/rumi/Desktop/projects/my_jobs_env/django-job-portal/accounts/api/views.py", line 13, in registration
    if not serializer.is_valid(raise_exception=True):
  File "/home/rumi/Desktop/projects/my_jobs_env/lib/python3.6/site-packages/rest_framework/serializers.py", line 242, in is_valid
    raise ValidationError(self.errors)
rest_framework.exceptions.ValidationError: {'email': [ErrorDetail(string='A user with that email already exists.', code='unique')]}

During handling of the above exception, another exception occurred:

Traceback (most recent call last):
  File "/home/rumi/Desktop/projects/my_jobs_env/lib/python3.6/site-packages/django/core/handlers/exception.py", line 34, in inner
    response = get_response(request)
  File "/home/rumi/Desktop/projects/my_jobs_env/lib/python3.6/site-packages/django/core/handlers/base.py", line 115, in _get_response
    response = self.process_exception_by_middleware(e, request)
  File "/home/rumi/Desktop/projects/my_jobs_env/lib/python3.6/site-packages/django/core/handlers/base.py", line 113, in _get_response
    response = wrapped_callback(request, *callback_args, **callback_kwargs)
  File "/home/rumi/Desktop/projects/my_jobs_env/lib/python3.6/site-packages/django/views/decorators/csrf.py", line 54, in wrapped_view
    return view_func(*args, **kwargs)
  File "/home/rumi/Desktop/projects/my_jobs_env/lib/python3.6/site-packages/django/views/generic/base.py", line 71, in view
    return self.dispatch(request, *args, **kwargs)
  File "/home/rumi/Desktop/projects/my_jobs_env/lib/python3.6/site-packages/rest_framework/views.py", line 505, in dispatch
    response = self.handle_exception(exc)
  File "/home/rumi/Desktop/projects/my_jobs_env/lib/python3.6/site-packages/rest_framework/views.py", line 462, in handle_exception
    response = exception_handler(exc, context)
  File "/home/rumi/Desktop/projects/my_jobs_env/django-job-portal/jobsapp/api/custom_exception.py", line 29, in custom_exception_handler
    response.data['message'] += value[0]
KeyError: 'message'
Internal Server Error: /api/register/
Traceback (most recent call last):
  File "/home/rumi/Desktop/projects/my_jobs_env/lib/python3.6/site-packages/rest_framework/views.py", line 502, in dispatch
    response = handler(request, *args, **kwargs)
  File "/home/rumi/Desktop/projects/my_jobs_env/lib/python3.6/site-packages/rest_framework/decorators.py", line 50, in handler
    return func(*args, **kwargs)
  File "/home/rumi/Desktop/projects/my_jobs_env/django-job-portal/accounts/api/views.py", line 13, in registration
    if not serializer.is_valid(raise_exception=True):
  File "/home/rumi/Desktop/projects/my_jobs_env/lib/python3.6/site-packages/rest_framework/serializers.py", line 242, in is_valid
    raise ValidationError(self.errors)
rest_framework.exceptions.ValidationError: {'email': [ErrorDetail(string='A user with that email already exists.', code='unique')]}

During handling of the above exception, another exception occurred:

Traceback (most recent call last):
  File "/home/rumi/Desktop/projects/my_jobs_env/lib/python3.6/site-packages/django/core/handlers/exception.py", line 34, in inner
    response = get_response(request)
  File "/home/rumi/Desktop/projects/my_jobs_env/lib/python3.6/site-packages/django/core/handlers/base.py", line 115, in _get_response
    response = self.process_exception_by_middleware(e, request)
  File "/home/rumi/Desktop/projects/my_jobs_env/lib/python3.6/site-packages/django/core/handlers/base.py", line 113, in _get_response
    response = wrapped_callback(request, *callback_args, **callback_kwargs)
  File "/home/rumi/Desktop/projects/my_jobs_env/lib/python3.6/site-packages/django/views/decorators/csrf.py", line 54, in wrapped_view
    return view_func(*args, **kwargs)
  File "/home/rumi/Desktop/projects/my_jobs_env/lib/python3.6/site-packages/django/views/generic/base.py", line 71, in view
    return self.dispatch(request, *args, **kwargs)
  File "/home/rumi/Desktop/projects/my_jobs_env/lib/python3.6/site-packages/rest_framework/views.py", line 505, in dispatch
    response = self.handle_exception(exc)
  File "/home/rumi/Desktop/projects/my_jobs_env/lib/python3.6/site-packages/rest_framework/views.py", line 462, in handle_exception
    response = exception_handler(exc, context)
  File "/home/rumi/Desktop/projects/my_jobs_env/django-job-portal/jobsapp/api/custom_exception.py", line 29, in custom_exception_handler
    response.data['message'] += value[0]
KeyError: 'message'
"POST /api/register/ HTTP/1.1" 500 112829
"POST /api/register/ HTTP/1.1" 500 112829
/home/rumi/Desktop/projects/my_jobs_env/django-job-portal/jobsapp/api/custom_exception.py changed, reloading.
/home/rumi/Desktop/projects/my_jobs_env/django-job-portal/jobsapp/api/custom_exception.py changed, reloading.
Watching for file changes with StatReloader
Watching for file changes with StatReloader
Bad Request: /api/register/
Bad Request: /api/register/
"POST /api/register/ HTTP/1.1" 400 126
"POST /api/register/ HTTP/1.1" 400 126
/home/rumi/Desktop/projects/my_jobs_env/django-job-portal/jobsapp/api/custom_exception.py changed, reloading.
/home/rumi/Desktop/projects/my_jobs_env/django-job-portal/jobsapp/api/custom_exception.py changed, reloading.
Watching for file changes with StatReloader
Watching for file changes with StatReloader
Bad Request: /api/register/
Bad Request: /api/register/
"POST /api/register/ HTTP/1.1" 400 127
"POST /api/register/ HTTP/1.1" 400 127
Internal Server Error: /api/register/
Traceback (most recent call last):
  File "/home/rumi/Desktop/projects/my_jobs_env/lib/python3.6/site-packages/django/core/handlers/exception.py", line 34, in inner
    response = get_response(request)
  File "/home/rumi/Desktop/projects/my_jobs_env/lib/python3.6/site-packages/django/core/handlers/base.py", line 115, in _get_response
    response = self.process_exception_by_middleware(e, request)
  File "/home/rumi/Desktop/projects/my_jobs_env/lib/python3.6/site-packages/django/core/handlers/base.py", line 113, in _get_response
    response = wrapped_callback(request, *callback_args, **callback_kwargs)
  File "/home/rumi/Desktop/projects/my_jobs_env/lib/python3.6/site-packages/django/views/decorators/csrf.py", line 54, in wrapped_view
    return view_func(*args, **kwargs)
  File "/home/rumi/Desktop/projects/my_jobs_env/lib/python3.6/site-packages/django/views/generic/base.py", line 71, in view
    return self.dispatch(request, *args, **kwargs)
  File "/home/rumi/Desktop/projects/my_jobs_env/lib/python3.6/site-packages/rest_framework/views.py", line 505, in dispatch
    response = self.handle_exception(exc)
  File "/home/rumi/Desktop/projects/my_jobs_env/lib/python3.6/site-packages/rest_framework/views.py", line 465, in handle_exception
    self.raise_uncaught_exception(exc)
  File "/home/rumi/Desktop/projects/my_jobs_env/lib/python3.6/site-packages/rest_framework/views.py", line 476, in raise_uncaught_exception
    raise exc
  File "/home/rumi/Desktop/projects/my_jobs_env/lib/python3.6/site-packages/rest_framework/views.py", line 502, in dispatch
    response = handler(request, *args, **kwargs)
  File "/home/rumi/Desktop/projects/my_jobs_env/lib/python3.6/site-packages/rest_framework/decorators.py", line 50, in handler
    return func(*args, **kwargs)
  File "/home/rumi/Desktop/projects/my_jobs_env/django-job-portal/accounts/api/views.py", line 15, in registration
    user = serializer.save()
  File "/home/rumi/Desktop/projects/my_jobs_env/lib/python3.6/site-packages/rest_framework/serializers.py", line 212, in save
    self.instance = self.create(validated_data)
  File "/home/rumi/Desktop/projects/my_jobs_env/django-job-portal/accounts/api/serializers.py", line 30, in create
    username = validated_data["username"]
KeyError: 'username'
Internal Server Error: /api/register/
Traceback (most recent call last):
  File "/home/rumi/Desktop/projects/my_jobs_env/lib/python3.6/site-packages/django/core/handlers/exception.py", line 34, in inner
    response = get_response(request)
  File "/home/rumi/Desktop/projects/my_jobs_env/lib/python3.6/site-packages/django/core/handlers/base.py", line 115, in _get_response
    response = self.process_exception_by_middleware(e, request)
  File "/home/rumi/Desktop/projects/my_jobs_env/lib/python3.6/site-packages/django/core/handlers/base.py", line 113, in _get_response
    response = wrapped_callback(request, *callback_args, **callback_kwargs)
  File "/home/rumi/Desktop/projects/my_jobs_env/lib/python3.6/site-packages/django/views/decorators/csrf.py", line 54, in wrapped_view
    return view_func(*args, **kwargs)
  File "/home/rumi/Desktop/projects/my_jobs_env/lib/python3.6/site-packages/django/views/generic/base.py", line 71, in view
    return self.dispatch(request, *args, **kwargs)
  File "/home/rumi/Desktop/projects/my_jobs_env/lib/python3.6/site-packages/rest_framework/views.py", line 505, in dispatch
    response = self.handle_exception(exc)
  File "/home/rumi/Desktop/projects/my_jobs_env/lib/python3.6/site-packages/rest_framework/views.py", line 465, in handle_exception
    self.raise_uncaught_exception(exc)
  File "/home/rumi/Desktop/projects/my_jobs_env/lib/python3.6/site-packages/rest_framework/views.py", line 476, in raise_uncaught_exception
    raise exc
  File "/home/rumi/Desktop/projects/my_jobs_env/lib/python3.6/site-packages/rest_framework/views.py", line 502, in dispatch
    response = handler(request, *args, **kwargs)
  File "/home/rumi/Desktop/projects/my_jobs_env/lib/python3.6/site-packages/rest_framework/decorators.py", line 50, in handler
    return func(*args, **kwargs)
  File "/home/rumi/Desktop/projects/my_jobs_env/django-job-portal/accounts/api/views.py", line 15, in registration
    user = serializer.save()
  File "/home/rumi/Desktop/projects/my_jobs_env/lib/python3.6/site-packages/rest_framework/serializers.py", line 212, in save
    self.instance = self.create(validated_data)
  File "/home/rumi/Desktop/projects/my_jobs_env/django-job-portal/accounts/api/serializers.py", line 30, in create
    username = validated_data["username"]
KeyError: 'username'
"POST /api/register/ HTTP/1.1" 500 19929
"POST /api/register/ HTTP/1.1" 500 19929
Internal Server Error: /api/register/
Traceback (most recent call last):
  File "/home/rumi/Desktop/projects/my_jobs_env/lib/python3.6/site-packages/django/core/handlers/exception.py", line 34, in inner
    response = get_response(request)
  File "/home/rumi/Desktop/projects/my_jobs_env/lib/python3.6/site-packages/django/core/handlers/base.py", line 115, in _get_response
    response = self.process_exception_by_middleware(e, request)
  File "/home/rumi/Desktop/projects/my_jobs_env/lib/python3.6/site-packages/django/core/handlers/base.py", line 113, in _get_response
    response = wrapped_callback(request, *callback_args, **callback_kwargs)
  File "/home/rumi/Desktop/projects/my_jobs_env/lib/python3.6/site-packages/django/views/decorators/csrf.py", line 54, in wrapped_view
    return view_func(*args, **kwargs)
  File "/home/rumi/Desktop/projects/my_jobs_env/lib/python3.6/site-packages/django/views/generic/base.py", line 71, in view
    return self.dispatch(request, *args, **kwargs)
  File "/home/rumi/Desktop/projects/my_jobs_env/lib/python3.6/site-packages/rest_framework/views.py", line 505, in dispatch
    response = self.handle_exception(exc)
  File "/home/rumi/Desktop/projects/my_jobs_env/lib/python3.6/site-packages/rest_framework/views.py", line 465, in handle_exception
    self.raise_uncaught_exception(exc)
  File "/home/rumi/Desktop/projects/my_jobs_env/lib/python3.6/site-packages/rest_framework/views.py", line 476, in raise_uncaught_exception
    raise exc
  File "/home/rumi/Desktop/projects/my_jobs_env/lib/python3.6/site-packages/rest_framework/views.py", line 502, in dispatch
    response = handler(request, *args, **kwargs)
  File "/home/rumi/Desktop/projects/my_jobs_env/lib/python3.6/site-packages/rest_framework/decorators.py", line 50, in handler
    return func(*args, **kwargs)
  File "/home/rumi/Desktop/projects/my_jobs_env/django-job-portal/accounts/api/views.py", line 15, in registration
    user = serializer.save()
  File "/home/rumi/Desktop/projects/my_jobs_env/lib/python3.6/site-packages/rest_framework/serializers.py", line 212, in save
    self.instance = self.create(validated_data)
  File "/home/rumi/Desktop/projects/my_jobs_env/django-job-portal/accounts/api/serializers.py", line 30, in create
    username = validated_data["username"]
KeyError: 'username'
Internal Server Error: /api/register/
Traceback (most recent call last):
  File "/home/rumi/Desktop/projects/my_jobs_env/lib/python3.6/site-packages/django/core/handlers/exception.py", line 34, in inner
    response = get_response(request)
  File "/home/rumi/Desktop/projects/my_jobs_env/lib/python3.6/site-packages/django/core/handlers/base.py", line 115, in _get_response
    response = self.process_exception_by_middleware(e, request)
  File "/home/rumi/Desktop/projects/my_jobs_env/lib/python3.6/site-packages/django/core/handlers/base.py", line 113, in _get_response
    response = wrapped_callback(request, *callback_args, **callback_kwargs)
  File "/home/rumi/Desktop/projects/my_jobs_env/lib/python3.6/site-packages/django/views/decorators/csrf.py", line 54, in wrapped_view
    return view_func(*args, **kwargs)
  File "/home/rumi/Desktop/projects/my_jobs_env/lib/python3.6/site-packages/django/views/generic/base.py", line 71, in view
    return self.dispatch(request, *args, **kwargs)
  File "/home/rumi/Desktop/projects/my_jobs_env/lib/python3.6/site-packages/rest_framework/views.py", line 505, in dispatch
    response = self.handle_exception(exc)
  File "/home/rumi/Desktop/projects/my_jobs_env/lib/python3.6/site-packages/rest_framework/views.py", line 465, in handle_exception
    self.raise_uncaught_exception(exc)
  File "/home/rumi/Desktop/projects/my_jobs_env/lib/python3.6/site-packages/rest_framework/views.py", line 476, in raise_uncaught_exception
    raise exc
  File "/home/rumi/Desktop/projects/my_jobs_env/lib/python3.6/site-packages/rest_framework/views.py", line 502, in dispatch
    response = handler(request, *args, **kwargs)
  File "/home/rumi/Desktop/projects/my_jobs_env/lib/python3.6/site-packages/rest_framework/decorators.py", line 50, in handler
    return func(*args, **kwargs)
  File "/home/rumi/Desktop/projects/my_jobs_env/django-job-portal/accounts/api/views.py", line 15, in registration
    user = serializer.save()
  File "/home/rumi/Desktop/projects/my_jobs_env/lib/python3.6/site-packages/rest_framework/serializers.py", line 212, in save
    self.instance = self.create(validated_data)
  File "/home/rumi/Desktop/projects/my_jobs_env/django-job-portal/accounts/api/serializers.py", line 30, in create
    username = validated_data["username"]
KeyError: 'username'
"POST /api/register/ HTTP/1.1" 500 19929
"POST /api/register/ HTTP/1.1" 500 19929
Internal Server Error: /api/register/
Traceback (most recent call last):
  File "/home/rumi/Desktop/projects/my_jobs_env/lib/python3.6/site-packages/django/core/handlers/exception.py", line 34, in inner
    response = get_response(request)
  File "/home/rumi/Desktop/projects/my_jobs_env/lib/python3.6/site-packages/django/core/handlers/base.py", line 115, in _get_response
    response = self.process_exception_by_middleware(e, request)
  File "/home/rumi/Desktop/projects/my_jobs_env/lib/python3.6/site-packages/django/core/handlers/base.py", line 113, in _get_response
    response = wrapped_callback(request, *callback_args, **callback_kwargs)
  File "/home/rumi/Desktop/projects/my_jobs_env/lib/python3.6/site-packages/django/views/decorators/csrf.py", line 54, in wrapped_view
    return view_func(*args, **kwargs)
  File "/home/rumi/Desktop/projects/my_jobs_env/lib/python3.6/site-packages/django/views/generic/base.py", line 71, in view
    return self.dispatch(request, *args, **kwargs)
  File "/home/rumi/Desktop/projects/my_jobs_env/lib/python3.6/site-packages/rest_framework/views.py", line 505, in dispatch
    response = self.handle_exception(exc)
  File "/home/rumi/Desktop/projects/my_jobs_env/lib/python3.6/site-packages/rest_framework/views.py", line 465, in handle_exception
    self.raise_uncaught_exception(exc)
  File "/home/rumi/Desktop/projects/my_jobs_env/lib/python3.6/site-packages/rest_framework/views.py", line 476, in raise_uncaught_exception
    raise exc
  File "/home/rumi/Desktop/projects/my_jobs_env/lib/python3.6/site-packages/rest_framework/views.py", line 502, in dispatch
    response = handler(request, *args, **kwargs)
  File "/home/rumi/Desktop/projects/my_jobs_env/lib/python3.6/site-packages/rest_framework/decorators.py", line 50, in handler
    return func(*args, **kwargs)
  File "/home/rumi/Desktop/projects/my_jobs_env/django-job-portal/accounts/api/views.py", line 15, in registration
    user = serializer.save()
  File "/home/rumi/Desktop/projects/my_jobs_env/lib/python3.6/site-packages/rest_framework/serializers.py", line 212, in save
    self.instance = self.create(validated_data)
  File "/home/rumi/Desktop/projects/my_jobs_env/django-job-portal/accounts/api/serializers.py", line 30, in create
    username = validated_data["username"]
KeyError: 'username'
Internal Server Error: /api/register/
Traceback (most recent call last):
  File "/home/rumi/Desktop/projects/my_jobs_env/lib/python3.6/site-packages/django/core/handlers/exception.py", line 34, in inner
    response = get_response(request)
  File "/home/rumi/Desktop/projects/my_jobs_env/lib/python3.6/site-packages/django/core/handlers/base.py", line 115, in _get_response
    response = self.process_exception_by_middleware(e, request)
  File "/home/rumi/Desktop/projects/my_jobs_env/lib/python3.6/site-packages/django/core/handlers/base.py", line 113, in _get_response
    response = wrapped_callback(request, *callback_args, **callback_kwargs)
  File "/home/rumi/Desktop/projects/my_jobs_env/lib/python3.6/site-packages/django/views/decorators/csrf.py", line 54, in wrapped_view
    return view_func(*args, **kwargs)
  File "/home/rumi/Desktop/projects/my_jobs_env/lib/python3.6/site-packages/django/views/generic/base.py", line 71, in view
    return self.dispatch(request, *args, **kwargs)
  File "/home/rumi/Desktop/projects/my_jobs_env/lib/python3.6/site-packages/rest_framework/views.py", line 505, in dispatch
    response = self.handle_exception(exc)
  File "/home/rumi/Desktop/projects/my_jobs_env/lib/python3.6/site-packages/rest_framework/views.py", line 465, in handle_exception
    self.raise_uncaught_exception(exc)
  File "/home/rumi/Desktop/projects/my_jobs_env/lib/python3.6/site-packages/rest_framework/views.py", line 476, in raise_uncaught_exception
    raise exc
  File "/home/rumi/Desktop/projects/my_jobs_env/lib/python3.6/site-packages/rest_framework/views.py", line 502, in dispatch
    response = handler(request, *args, **kwargs)
  File "/home/rumi/Desktop/projects/my_jobs_env/lib/python3.6/site-packages/rest_framework/decorators.py", line 50, in handler
    return func(*args, **kwargs)
  File "/home/rumi/Desktop/projects/my_jobs_env/django-job-portal/accounts/api/views.py", line 15, in registration
    user = serializer.save()
  File "/home/rumi/Desktop/projects/my_jobs_env/lib/python3.6/site-packages/rest_framework/serializers.py", line 212, in save
    self.instance = self.create(validated_data)
  File "/home/rumi/Desktop/projects/my_jobs_env/django-job-portal/accounts/api/serializers.py", line 30, in create
    username = validated_data["username"]
KeyError: 'username'
"POST /api/register/ HTTP/1.1" 500 19929
"POST /api/register/ HTTP/1.1" 500 19929
Internal Server Error: /api/register/
Traceback (most recent call last):
  File "/home/rumi/Desktop/projects/my_jobs_env/lib/python3.6/site-packages/django/core/handlers/exception.py", line 34, in inner
    response = get_response(request)
  File "/home/rumi/Desktop/projects/my_jobs_env/lib/python3.6/site-packages/django/core/handlers/base.py", line 115, in _get_response
    response = self.process_exception_by_middleware(e, request)
  File "/home/rumi/Desktop/projects/my_jobs_env/lib/python3.6/site-packages/django/core/handlers/base.py", line 113, in _get_response
    response = wrapped_callback(request, *callback_args, **callback_kwargs)
  File "/home/rumi/Desktop/projects/my_jobs_env/lib/python3.6/site-packages/django/views/decorators/csrf.py", line 54, in wrapped_view
    return view_func(*args, **kwargs)
  File "/home/rumi/Desktop/projects/my_jobs_env/lib/python3.6/site-packages/django/views/generic/base.py", line 71, in view
    return self.dispatch(request, *args, **kwargs)
  File "/home/rumi/Desktop/projects/my_jobs_env/lib/python3.6/site-packages/rest_framework/views.py", line 505, in dispatch
    response = self.handle_exception(exc)
  File "/home/rumi/Desktop/projects/my_jobs_env/lib/python3.6/site-packages/rest_framework/views.py", line 465, in handle_exception
    self.raise_uncaught_exception(exc)
  File "/home/rumi/Desktop/projects/my_jobs_env/lib/python3.6/site-packages/rest_framework/views.py", line 476, in raise_uncaught_exception
    raise exc
  File "/home/rumi/Desktop/projects/my_jobs_env/lib/python3.6/site-packages/rest_framework/views.py", line 502, in dispatch
    response = handler(request, *args, **kwargs)
  File "/home/rumi/Desktop/projects/my_jobs_env/lib/python3.6/site-packages/rest_framework/decorators.py", line 50, in handler
    return func(*args, **kwargs)
  File "/home/rumi/Desktop/projects/my_jobs_env/django-job-portal/accounts/api/views.py", line 15, in registration
    user = serializer.save()
  File "/home/rumi/Desktop/projects/my_jobs_env/lib/python3.6/site-packages/rest_framework/serializers.py", line 212, in save
    self.instance = self.create(validated_data)
  File "/home/rumi/Desktop/projects/my_jobs_env/django-job-portal/accounts/api/serializers.py", line 30, in create
    username = validated_data["username"]
KeyError: 'username'
Internal Server Error: /api/register/
Traceback (most recent call last):
  File "/home/rumi/Desktop/projects/my_jobs_env/lib/python3.6/site-packages/django/core/handlers/exception.py", line 34, in inner
    response = get_response(request)
  File "/home/rumi/Desktop/projects/my_jobs_env/lib/python3.6/site-packages/django/core/handlers/base.py", line 115, in _get_response
    response = self.process_exception_by_middleware(e, request)
  File "/home/rumi/Desktop/projects/my_jobs_env/lib/python3.6/site-packages/django/core/handlers/base.py", line 113, in _get_response
    response = wrapped_callback(request, *callback_args, **callback_kwargs)
  File "/home/rumi/Desktop/projects/my_jobs_env/lib/python3.6/site-packages/django/views/decorators/csrf.py", line 54, in wrapped_view
    return view_func(*args, **kwargs)
  File "/home/rumi/Desktop/projects/my_jobs_env/lib/python3.6/site-packages/django/views/generic/base.py", line 71, in view
    return self.dispatch(request, *args, **kwargs)
  File "/home/rumi/Desktop/projects/my_jobs_env/lib/python3.6/site-packages/rest_framework/views.py", line 505, in dispatch
    response = self.handle_exception(exc)
  File "/home/rumi/Desktop/projects/my_jobs_env/lib/python3.6/site-packages/rest_framework/views.py", line 465, in handle_exception
    self.raise_uncaught_exception(exc)
  File "/home/rumi/Desktop/projects/my_jobs_env/lib/python3.6/site-packages/rest_framework/views.py", line 476, in raise_uncaught_exception
    raise exc
  File "/home/rumi/Desktop/projects/my_jobs_env/lib/python3.6/site-packages/rest_framework/views.py", line 502, in dispatch
    response = handler(request, *args, **kwargs)
  File "/home/rumi/Desktop/projects/my_jobs_env/lib/python3.6/site-packages/rest_framework/decorators.py", line 50, in handler
    return func(*args, **kwargs)
  File "/home/rumi/Desktop/projects/my_jobs_env/django-job-portal/accounts/api/views.py", line 15, in registration
    user = serializer.save()
  File "/home/rumi/Desktop/projects/my_jobs_env/lib/python3.6/site-packages/rest_framework/serializers.py", line 212, in save
    self.instance = self.create(validated_data)
  File "/home/rumi/Desktop/projects/my_jobs_env/django-job-portal/accounts/api/serializers.py", line 30, in create
    username = validated_data["username"]
KeyError: 'username'
"POST /api/register/ HTTP/1.1" 500 19929
"POST /api/register/ HTTP/1.1" 500 19929
/home/rumi/Desktop/projects/my_jobs_env/django-job-portal/accounts/api/serializers.py changed, reloading.
/home/rumi/Desktop/projects/my_jobs_env/django-job-portal/accounts/api/serializers.py changed, reloading.
Watching for file changes with StatReloader
Watching for file changes with StatReloader
Internal Server Error: /api/register/
Traceback (most recent call last):
  File "/home/rumi/Desktop/projects/my_jobs_env/lib/python3.6/site-packages/django/core/handlers/exception.py", line 34, in inner
    response = get_response(request)
  File "/home/rumi/Desktop/projects/my_jobs_env/lib/python3.6/site-packages/django/core/handlers/base.py", line 115, in _get_response
    response = self.process_exception_by_middleware(e, request)
  File "/home/rumi/Desktop/projects/my_jobs_env/lib/python3.6/site-packages/django/core/handlers/base.py", line 113, in _get_response
    response = wrapped_callback(request, *callback_args, **callback_kwargs)
  File "/home/rumi/Desktop/projects/my_jobs_env/lib/python3.6/site-packages/django/views/decorators/csrf.py", line 54, in wrapped_view
    return view_func(*args, **kwargs)
  File "/home/rumi/Desktop/projects/my_jobs_env/lib/python3.6/site-packages/django/views/generic/base.py", line 71, in view
    return self.dispatch(request, *args, **kwargs)
  File "/home/rumi/Desktop/projects/my_jobs_env/lib/python3.6/site-packages/rest_framework/views.py", line 505, in dispatch
    response = self.handle_exception(exc)
  File "/home/rumi/Desktop/projects/my_jobs_env/lib/python3.6/site-packages/rest_framework/views.py", line 465, in handle_exception
    self.raise_uncaught_exception(exc)
  File "/home/rumi/Desktop/projects/my_jobs_env/lib/python3.6/site-packages/rest_framework/views.py", line 476, in raise_uncaught_exception
    raise exc
  File "/home/rumi/Desktop/projects/my_jobs_env/lib/python3.6/site-packages/rest_framework/views.py", line 502, in dispatch
    response = handler(request, *args, **kwargs)
  File "/home/rumi/Desktop/projects/my_jobs_env/lib/python3.6/site-packages/rest_framework/decorators.py", line 50, in handler
    return func(*args, **kwargs)
  File "/home/rumi/Desktop/projects/my_jobs_env/django-job-portal/accounts/api/views.py", line 15, in registration
    user = serializer.save()
  File "/home/rumi/Desktop/projects/my_jobs_env/lib/python3.6/site-packages/rest_framework/serializers.py", line 212, in save
    self.instance = self.create(validated_data)
  File "/home/rumi/Desktop/projects/my_jobs_env/django-job-portal/accounts/api/serializers.py", line 31, in create
    username = validated_data["username"]
KeyError: 'username'
Internal Server Error: /api/register/
Traceback (most recent call last):
  File "/home/rumi/Desktop/projects/my_jobs_env/lib/python3.6/site-packages/django/core/handlers/exception.py", line 34, in inner
    response = get_response(request)
  File "/home/rumi/Desktop/projects/my_jobs_env/lib/python3.6/site-packages/django/core/handlers/base.py", line 115, in _get_response
    response = self.process_exception_by_middleware(e, request)
  File "/home/rumi/Desktop/projects/my_jobs_env/lib/python3.6/site-packages/django/core/handlers/base.py", line 113, in _get_response
    response = wrapped_callback(request, *callback_args, **callback_kwargs)
  File "/home/rumi/Desktop/projects/my_jobs_env/lib/python3.6/site-packages/django/views/decorators/csrf.py", line 54, in wrapped_view
    return view_func(*args, **kwargs)
  File "/home/rumi/Desktop/projects/my_jobs_env/lib/python3.6/site-packages/django/views/generic/base.py", line 71, in view
    return self.dispatch(request, *args, **kwargs)
  File "/home/rumi/Desktop/projects/my_jobs_env/lib/python3.6/site-packages/rest_framework/views.py", line 505, in dispatch
    response = self.handle_exception(exc)
  File "/home/rumi/Desktop/projects/my_jobs_env/lib/python3.6/site-packages/rest_framework/views.py", line 465, in handle_exception
    self.raise_uncaught_exception(exc)
  File "/home/rumi/Desktop/projects/my_jobs_env/lib/python3.6/site-packages/rest_framework/views.py", line 476, in raise_uncaught_exception
    raise exc
  File "/home/rumi/Desktop/projects/my_jobs_env/lib/python3.6/site-packages/rest_framework/views.py", line 502, in dispatch
    response = handler(request, *args, **kwargs)
  File "/home/rumi/Desktop/projects/my_jobs_env/lib/python3.6/site-packages/rest_framework/decorators.py", line 50, in handler
    return func(*args, **kwargs)
  File "/home/rumi/Desktop/projects/my_jobs_env/django-job-portal/accounts/api/views.py", line 15, in registration
    user = serializer.save()
  File "/home/rumi/Desktop/projects/my_jobs_env/lib/python3.6/site-packages/rest_framework/serializers.py", line 212, in save
    self.instance = self.create(validated_data)
  File "/home/rumi/Desktop/projects/my_jobs_env/django-job-portal/accounts/api/serializers.py", line 31, in create
    username = validated_data["username"]
KeyError: 'username'
"POST /api/register/ HTTP/1.1" 500 19929
"POST /api/register/ HTTP/1.1" 500 19929
/home/rumi/Desktop/projects/my_jobs_env/django-job-portal/accounts/api/serializers.py changed, reloading.
/home/rumi/Desktop/projects/my_jobs_env/django-job-portal/accounts/api/serializers.py changed, reloading.
Watching for file changes with StatReloader
Watching for file changes with StatReloader
/home/rumi/Desktop/projects/my_jobs_env/django-job-portal/accounts/api/serializers.py changed, reloading.
/home/rumi/Desktop/projects/my_jobs_env/django-job-portal/accounts/api/serializers.py changed, reloading.
Watching for file changes with StatReloader
Watching for file changes with StatReloader
"POST /api/register/ HTTP/1.1" 201 438
"POST /api/register/ HTTP/1.1" 201 438
/home/rumi/Desktop/projects/my_jobs_env/django-job-portal/accounts/api/views.py changed, reloading.
/home/rumi/Desktop/projects/my_jobs_env/django-job-portal/accounts/api/views.py changed, reloading.
Watching for file changes with StatReloader
Watching for file changes with StatReloader
Bad Request: /api/register/
Bad Request: /api/register/
"POST /api/register/ HTTP/1.1" 400 127
"POST /api/register/ HTTP/1.1" 400 127
"POST /api/register/ HTTP/1.1" 201 51
"POST /api/register/ HTTP/1.1" 201 51
/home/rumi/Desktop/projects/my_jobs_env/lib/python3.6/site-packages/django/urls/base.py changed, reloading.
/home/rumi/Desktop/projects/my_jobs_env/lib/python3.6/site-packages/django/urls/base.py changed, reloading.
