POST http://localhost:9200/_bulk?refresh=true [status:N/A request:0.001s]
Traceback (most recent call last):
  File "/home/rumi/Desktop/projects/django/job_env/lib/python3.8/site-packages/urllib3/connection.py", line 159, in _new_conn
    conn = connection.create_connection(
  File "/home/rumi/Desktop/projects/django/job_env/lib/python3.8/site-packages/urllib3/util/connection.py", line 84, in create_connection
    raise err
  File "/home/rumi/Desktop/projects/django/job_env/lib/python3.8/site-packages/urllib3/util/connection.py", line 74, in create_connection
    sock.connect(sa)
ConnectionRefusedError: [Errno 111] Connection refused

During handling of the above exception, another exception occurred:

Traceback (most recent call last):
  File "/home/rumi/Desktop/projects/django/job_env/lib/python3.8/site-packages/elasticsearch/connection/http_urllib3.py", line 241, in perform_request
    response = self.pool.urlopen(
  File "/home/rumi/Desktop/projects/django/job_env/lib/python3.8/site-packages/urllib3/connectionpool.py", line 719, in urlopen
    retries = retries.increment(
  File "/home/rumi/Desktop/projects/django/job_env/lib/python3.8/site-packages/urllib3/util/retry.py", line 376, in increment
    raise six.reraise(type(error), error, _stacktrace)
  File "/home/rumi/Desktop/projects/django/job_env/lib/python3.8/site-packages/six.py", line 703, in reraise
    raise value
  File "/home/rumi/Desktop/projects/django/job_env/lib/python3.8/site-packages/urllib3/connectionpool.py", line 665, in urlopen
    httplib_response = self._make_request(
  File "/home/rumi/Desktop/projects/django/job_env/lib/python3.8/site-packages/urllib3/connectionpool.py", line 387, in _make_request
    conn.request(method, url, **httplib_request_kw)
  File "/usr/lib/python3.8/http/client.py", line 1255, in request
    self._send_request(method, url, body, headers, encode_chunked)
  File "/usr/lib/python3.8/http/client.py", line 1301, in _send_request
    self.endheaders(body, encode_chunked=encode_chunked)
  File "/usr/lib/python3.8/http/client.py", line 1250, in endheaders
    self._send_output(message_body, encode_chunked=encode_chunked)
  File "/usr/lib/python3.8/http/client.py", line 1010, in _send_output
    self.send(msg)
  File "/usr/lib/python3.8/http/client.py", line 950, in send
    self.connect()
  File "/home/rumi/Desktop/projects/django/job_env/lib/python3.8/site-packages/urllib3/connection.py", line 187, in connect
    conn = self._new_conn()
  File "/home/rumi/Desktop/projects/django/job_env/lib/python3.8/site-packages/urllib3/connection.py", line 171, in _new_conn
    raise NewConnectionError(
urllib3.exceptions.NewConnectionError: <urllib3.connection.HTTPConnection object at 0x7fe49681ca30>: Failed to establish a new connection: [Errno 111] Connection refused
POST http://localhost:9200/_bulk?refresh=true [status:N/A request:0.000s]
Traceback (most recent call last):
  File "/home/rumi/Desktop/projects/django/job_env/lib/python3.8/site-packages/urllib3/connection.py", line 159, in _new_conn
    conn = connection.create_connection(
  File "/home/rumi/Desktop/projects/django/job_env/lib/python3.8/site-packages/urllib3/util/connection.py", line 84, in create_connection
    raise err
  File "/home/rumi/Desktop/projects/django/job_env/lib/python3.8/site-packages/urllib3/util/connection.py", line 74, in create_connection
    sock.connect(sa)
ConnectionRefusedError: [Errno 111] Connection refused

During handling of the above exception, another exception occurred:

Traceback (most recent call last):
  File "/home/rumi/Desktop/projects/django/job_env/lib/python3.8/site-packages/elasticsearch/connection/http_urllib3.py", line 241, in perform_request
    response = self.pool.urlopen(
  File "/home/rumi/Desktop/projects/django/job_env/lib/python3.8/site-packages/urllib3/connectionpool.py", line 719, in urlopen
    retries = retries.increment(
  File "/home/rumi/Desktop/projects/django/job_env/lib/python3.8/site-packages/urllib3/util/retry.py", line 376, in increment
    raise six.reraise(type(error), error, _stacktrace)
  File "/home/rumi/Desktop/projects/django/job_env/lib/python3.8/site-packages/six.py", line 703, in reraise
    raise value
  File "/home/rumi/Desktop/projects/django/job_env/lib/python3.8/site-packages/urllib3/connectionpool.py", line 665, in urlopen
    httplib_response = self._make_request(
  File "/home/rumi/Desktop/projects/django/job_env/lib/python3.8/site-packages/urllib3/connectionpool.py", line 387, in _make_request
    conn.request(method, url, **httplib_request_kw)
  File "/usr/lib/python3.8/http/client.py", line 1255, in request
    self._send_request(method, url, body, headers, encode_chunked)
  File "/usr/lib/python3.8/http/client.py", line 1301, in _send_request
    self.endheaders(body, encode_chunked=encode_chunked)
  File "/usr/lib/python3.8/http/client.py", line 1250, in endheaders
    self._send_output(message_body, encode_chunked=encode_chunked)
  File "/usr/lib/python3.8/http/client.py", line 1010, in _send_output
    self.send(msg)
  File "/usr/lib/python3.8/http/client.py", line 950, in send
    self.connect()
  File "/home/rumi/Desktop/projects/django/job_env/lib/python3.8/site-packages/urllib3/connection.py", line 187, in connect
    conn = self._new_conn()
  File "/home/rumi/Desktop/projects/django/job_env/lib/python3.8/site-packages/urllib3/connection.py", line 171, in _new_conn
    raise NewConnectionError(
urllib3.exceptions.NewConnectionError: <urllib3.connection.HTTPConnection object at 0x7fe49660cfd0>: Failed to establish a new connection: [Errno 111] Connection refused
POST http://localhost:9200/_bulk?refresh=true [status:N/A request:0.000s]
Traceback (most recent call last):
  File "/home/rumi/Desktop/projects/django/job_env/lib/python3.8/site-packages/urllib3/connection.py", line 159, in _new_conn
    conn = connection.create_connection(
  File "/home/rumi/Desktop/projects/django/job_env/lib/python3.8/site-packages/urllib3/util/connection.py", line 84, in create_connection
    raise err
  File "/home/rumi/Desktop/projects/django/job_env/lib/python3.8/site-packages/urllib3/util/connection.py", line 74, in create_connection
    sock.connect(sa)
ConnectionRefusedError: [Errno 111] Connection refused

During handling of the above exception, another exception occurred:

Traceback (most recent call last):
  File "/home/rumi/Desktop/projects/django/job_env/lib/python3.8/site-packages/elasticsearch/connection/http_urllib3.py", line 241, in perform_request
    response = self.pool.urlopen(
  File "/home/rumi/Desktop/projects/django/job_env/lib/python3.8/site-packages/urllib3/connectionpool.py", line 719, in urlopen
    retries = retries.increment(
  File "/home/rumi/Desktop/projects/django/job_env/lib/python3.8/site-packages/urllib3/util/retry.py", line 376, in increment
    raise six.reraise(type(error), error, _stacktrace)
  File "/home/rumi/Desktop/projects/django/job_env/lib/python3.8/site-packages/six.py", line 703, in reraise
    raise value
  File "/home/rumi/Desktop/projects/django/job_env/lib/python3.8/site-packages/urllib3/connectionpool.py", line 665, in urlopen
    httplib_response = self._make_request(
  File "/home/rumi/Desktop/projects/django/job_env/lib/python3.8/site-packages/urllib3/connectionpool.py", line 387, in _make_request
    conn.request(method, url, **httplib_request_kw)
  File "/usr/lib/python3.8/http/client.py", line 1255, in request
    self._send_request(method, url, body, headers, encode_chunked)
  File "/usr/lib/python3.8/http/client.py", line 1301, in _send_request
    self.endheaders(body, encode_chunked=encode_chunked)
  File "/usr/lib/python3.8/http/client.py", line 1250, in endheaders
    self._send_output(message_body, encode_chunked=encode_chunked)
  File "/usr/lib/python3.8/http/client.py", line 1010, in _send_output
    self.send(msg)
  File "/usr/lib/python3.8/http/client.py", line 950, in send
    self.connect()
  File "/home/rumi/Desktop/projects/django/job_env/lib/python3.8/site-packages/urllib3/connection.py", line 187, in connect
    conn = self._new_conn()
  File "/home/rumi/Desktop/projects/django/job_env/lib/python3.8/site-packages/urllib3/connection.py", line 171, in _new_conn
    raise NewConnectionError(
urllib3.exceptions.NewConnectionError: <urllib3.connection.HTTPConnection object at 0x7fe49661e310>: Failed to establish a new connection: [Errno 111] Connection refused
POST http://localhost:9200/_bulk?refresh=true [status:N/A request:0.000s]
Traceback (most recent call last):
  File "/home/rumi/Desktop/projects/django/job_env/lib/python3.8/site-packages/urllib3/connection.py", line 159, in _new_conn
    conn = connection.create_connection(
  File "/home/rumi/Desktop/projects/django/job_env/lib/python3.8/site-packages/urllib3/util/connection.py", line 84, in create_connection
    raise err
  File "/home/rumi/Desktop/projects/django/job_env/lib/python3.8/site-packages/urllib3/util/connection.py", line 74, in create_connection
    sock.connect(sa)
ConnectionRefusedError: [Errno 111] Connection refused

During handling of the above exception, another exception occurred:

Traceback (most recent call last):
  File "/home/rumi/Desktop/projects/django/job_env/lib/python3.8/site-packages/elasticsearch/connection/http_urllib3.py", line 241, in perform_request
    response = self.pool.urlopen(
  File "/home/rumi/Desktop/projects/django/job_env/lib/python3.8/site-packages/urllib3/connectionpool.py", line 719, in urlopen
    retries = retries.increment(
  File "/home/rumi/Desktop/projects/django/job_env/lib/python3.8/site-packages/urllib3/util/retry.py", line 376, in increment
    raise six.reraise(type(error), error, _stacktrace)
  File "/home/rumi/Desktop/projects/django/job_env/lib/python3.8/site-packages/six.py", line 703, in reraise
    raise value
  File "/home/rumi/Desktop/projects/django/job_env/lib/python3.8/site-packages/urllib3/connectionpool.py", line 665, in urlopen
    httplib_response = self._make_request(
  File "/home/rumi/Desktop/projects/django/job_env/lib/python3.8/site-packages/urllib3/connectionpool.py", line 387, in _make_request
    conn.request(method, url, **httplib_request_kw)
  File "/usr/lib/python3.8/http/client.py", line 1255, in request
    self._send_request(method, url, body, headers, encode_chunked)
  File "/usr/lib/python3.8/http/client.py", line 1301, in _send_request
    self.endheaders(body, encode_chunked=encode_chunked)
  File "/usr/lib/python3.8/http/client.py", line 1250, in endheaders
    self._send_output(message_body, encode_chunked=encode_chunked)
  File "/usr/lib/python3.8/http/client.py", line 1010, in _send_output
    self.send(msg)
  File "/usr/lib/python3.8/http/client.py", line 950, in send
    self.connect()
  File "/home/rumi/Desktop/projects/django/job_env/lib/python3.8/site-packages/urllib3/connection.py", line 187, in connect
    conn = self._new_conn()
  File "/home/rumi/Desktop/projects/django/job_env/lib/python3.8/site-packages/urllib3/connection.py", line 171, in _new_conn
    raise NewConnectionError(
urllib3.exceptions.NewConnectionError: <urllib3.connection.HTTPConnection object at 0x7fe49661e370>: Failed to establish a new connection: [Errno 111] Connection refused
POST http://localhost:9200/_bulk?refresh=true [status:N/A request:0.001s]
Traceback (most recent call last):
  File "/home/rumi/Desktop/projects/django/job_env/lib/python3.8/site-packages/urllib3/connection.py", line 159, in _new_conn
    conn = connection.create_connection(
  File "/home/rumi/Desktop/projects/django/job_env/lib/python3.8/site-packages/urllib3/util/connection.py", line 84, in create_connection
    raise err
  File "/home/rumi/Desktop/projects/django/job_env/lib/python3.8/site-packages/urllib3/util/connection.py", line 74, in create_connection
    sock.connect(sa)
ConnectionRefusedError: [Errno 111] Connection refused

During handling of the above exception, another exception occurred:

Traceback (most recent call last):
  File "/home/rumi/Desktop/projects/django/job_env/lib/python3.8/site-packages/elasticsearch/connection/http_urllib3.py", line 241, in perform_request
    response = self.pool.urlopen(
  File "/home/rumi/Desktop/projects/django/job_env/lib/python3.8/site-packages/urllib3/connectionpool.py", line 719, in urlopen
    retries = retries.increment(
  File "/home/rumi/Desktop/projects/django/job_env/lib/python3.8/site-packages/urllib3/util/retry.py", line 376, in increment
    raise six.reraise(type(error), error, _stacktrace)
  File "/home/rumi/Desktop/projects/django/job_env/lib/python3.8/site-packages/six.py", line 703, in reraise
    raise value
  File "/home/rumi/Desktop/projects/django/job_env/lib/python3.8/site-packages/urllib3/connectionpool.py", line 665, in urlopen
    httplib_response = self._make_request(
  File "/home/rumi/Desktop/projects/django/job_env/lib/python3.8/site-packages/urllib3/connectionpool.py", line 387, in _make_request
    conn.request(method, url, **httplib_request_kw)
  File "/usr/lib/python3.8/http/client.py", line 1255, in request
    self._send_request(method, url, body, headers, encode_chunked)
  File "/usr/lib/python3.8/http/client.py", line 1301, in _send_request
    self.endheaders(body, encode_chunked=encode_chunked)
  File "/usr/lib/python3.8/http/client.py", line 1250, in endheaders
    self._send_output(message_body, encode_chunked=encode_chunked)
  File "/usr/lib/python3.8/http/client.py", line 1010, in _send_output
    self.send(msg)
  File "/usr/lib/python3.8/http/client.py", line 950, in send
    self.connect()
  File "/home/rumi/Desktop/projects/django/job_env/lib/python3.8/site-packages/urllib3/connection.py", line 187, in connect
    conn = self._new_conn()
  File "/home/rumi/Desktop/projects/django/job_env/lib/python3.8/site-packages/urllib3/connection.py", line 171, in _new_conn
    raise NewConnectionError(
urllib3.exceptions.NewConnectionError: <urllib3.connection.HTTPConnection object at 0x7f721f9c9a30>: Failed to establish a new connection: [Errno 111] Connection refused
POST http://localhost:9200/_bulk?refresh=true [status:N/A request:0.001s]
Traceback (most recent call last):
  File "/home/rumi/Desktop/projects/django/job_env/lib/python3.8/site-packages/urllib3/connection.py", line 159, in _new_conn
    conn = connection.create_connection(
  File "/home/rumi/Desktop/projects/django/job_env/lib/python3.8/site-packages/urllib3/util/connection.py", line 84, in create_connection
    raise err
  File "/home/rumi/Desktop/projects/django/job_env/lib/python3.8/site-packages/urllib3/util/connection.py", line 74, in create_connection
    sock.connect(sa)
ConnectionRefusedError: [Errno 111] Connection refused

During handling of the above exception, another exception occurred:

Traceback (most recent call last):
  File "/home/rumi/Desktop/projects/django/job_env/lib/python3.8/site-packages/elasticsearch/connection/http_urllib3.py", line 241, in perform_request
    response = self.pool.urlopen(
  File "/home/rumi/Desktop/projects/django/job_env/lib/python3.8/site-packages/urllib3/connectionpool.py", line 719, in urlopen
    retries = retries.increment(
  File "/home/rumi/Desktop/projects/django/job_env/lib/python3.8/site-packages/urllib3/util/retry.py", line 376, in increment
    raise six.reraise(type(error), error, _stacktrace)
  File "/home/rumi/Desktop/projects/django/job_env/lib/python3.8/site-packages/six.py", line 703, in reraise
    raise value
  File "/home/rumi/Desktop/projects/django/job_env/lib/python3.8/site-packages/urllib3/connectionpool.py", line 665, in urlopen
    httplib_response = self._make_request(
  File "/home/rumi/Desktop/projects/django/job_env/lib/python3.8/site-packages/urllib3/connectionpool.py", line 387, in _make_request
    conn.request(method, url, **httplib_request_kw)
  File "/usr/lib/python3.8/http/client.py", line 1255, in request
    self._send_request(method, url, body, headers, encode_chunked)
  File "/usr/lib/python3.8/http/client.py", line 1301, in _send_request
    self.endheaders(body, encode_chunked=encode_chunked)
  File "/usr/lib/python3.8/http/client.py", line 1250, in endheaders
    self._send_output(message_body, encode_chunked=encode_chunked)
  File "/usr/lib/python3.8/http/client.py", line 1010, in _send_output
    self.send(msg)
  File "/usr/lib/python3.8/http/client.py", line 950, in send
    self.connect()
  File "/home/rumi/Desktop/projects/django/job_env/lib/python3.8/site-packages/urllib3/connection.py", line 187, in connect
    conn = self._new_conn()
  File "/home/rumi/Desktop/projects/django/job_env/lib/python3.8/site-packages/urllib3/connection.py", line 171, in _new_conn
    raise NewConnectionError(
urllib3.exceptions.NewConnectionError: <urllib3.connection.HTTPConnection object at 0x7f721f6b6fd0>: Failed to establish a new connection: [Errno 111] Connection refused
POST http://localhost:9200/_bulk?refresh=true [status:N/A request:0.000s]
Traceback (most recent call last):
  File "/home/rumi/Desktop/projects/django/job_env/lib/python3.8/site-packages/urllib3/connection.py", line 159, in _new_conn
    conn = connection.create_connection(
  File "/home/rumi/Desktop/projects/django/job_env/lib/python3.8/site-packages/urllib3/util/connection.py", line 84, in create_connection
    raise err
  File "/home/rumi/Desktop/projects/django/job_env/lib/python3.8/site-packages/urllib3/util/connection.py", line 74, in create_connection
    sock.connect(sa)
ConnectionRefusedError: [Errno 111] Connection refused

During handling of the above exception, another exception occurred:

Traceback (most recent call last):
  File "/home/rumi/Desktop/projects/django/job_env/lib/python3.8/site-packages/elasticsearch/connection/http_urllib3.py", line 241, in perform_request
    response = self.pool.urlopen(
  File "/home/rumi/Desktop/projects/django/job_env/lib/python3.8/site-packages/urllib3/connectionpool.py", line 719, in urlopen
    retries = retries.increment(
  File "/home/rumi/Desktop/projects/django/job_env/lib/python3.8/site-packages/urllib3/util/retry.py", line 376, in increment
    raise six.reraise(type(error), error, _stacktrace)
  File "/home/rumi/Desktop/projects/django/job_env/lib/python3.8/site-packages/six.py", line 703, in reraise
    raise value
  File "/home/rumi/Desktop/projects/django/job_env/lib/python3.8/site-packages/urllib3/connectionpool.py", line 665, in urlopen
    httplib_response = self._make_request(
  File "/home/rumi/Desktop/projects/django/job_env/lib/python3.8/site-packages/urllib3/connectionpool.py", line 387, in _make_request
    conn.request(method, url, **httplib_request_kw)
  File "/usr/lib/python3.8/http/client.py", line 1255, in request
    self._send_request(method, url, body, headers, encode_chunked)
  File "/usr/lib/python3.8/http/client.py", line 1301, in _send_request
    self.endheaders(body, encode_chunked=encode_chunked)
  File "/usr/lib/python3.8/http/client.py", line 1250, in endheaders
    self._send_output(message_body, encode_chunked=encode_chunked)
  File "/usr/lib/python3.8/http/client.py", line 1010, in _send_output
    self.send(msg)
  File "/usr/lib/python3.8/http/client.py", line 950, in send
    self.connect()
  File "/home/rumi/Desktop/projects/django/job_env/lib/python3.8/site-packages/urllib3/connection.py", line 187, in connect
    conn = self._new_conn()
  File "/home/rumi/Desktop/projects/django/job_env/lib/python3.8/site-packages/urllib3/connection.py", line 171, in _new_conn
    raise NewConnectionError(
urllib3.exceptions.NewConnectionError: <urllib3.connection.HTTPConnection object at 0x7f721f6ca310>: Failed to establish a new connection: [Errno 111] Connection refused
POST http://localhost:9200/_bulk?refresh=true [status:N/A request:0.000s]
Traceback (most recent call last):
  File "/home/rumi/Desktop/projects/django/job_env/lib/python3.8/site-packages/urllib3/connection.py", line 159, in _new_conn
    conn = connection.create_connection(
  File "/home/rumi/Desktop/projects/django/job_env/lib/python3.8/site-packages/urllib3/util/connection.py", line 84, in create_connection
    raise err
  File "/home/rumi/Desktop/projects/django/job_env/lib/python3.8/site-packages/urllib3/util/connection.py", line 74, in create_connection
    sock.connect(sa)
ConnectionRefusedError: [Errno 111] Connection refused

During handling of the above exception, another exception occurred:

Traceback (most recent call last):
  File "/home/rumi/Desktop/projects/django/job_env/lib/python3.8/site-packages/elasticsearch/connection/http_urllib3.py", line 241, in perform_request
    response = self.pool.urlopen(
  File "/home/rumi/Desktop/projects/django/job_env/lib/python3.8/site-packages/urllib3/connectionpool.py", line 719, in urlopen
    retries = retries.increment(
  File "/home/rumi/Desktop/projects/django/job_env/lib/python3.8/site-packages/urllib3/util/retry.py", line 376, in increment
    raise six.reraise(type(error), error, _stacktrace)
  File "/home/rumi/Desktop/projects/django/job_env/lib/python3.8/site-packages/six.py", line 703, in reraise
    raise value
  File "/home/rumi/Desktop/projects/django/job_env/lib/python3.8/site-packages/urllib3/connectionpool.py", line 665, in urlopen
    httplib_response = self._make_request(
  File "/home/rumi/Desktop/projects/django/job_env/lib/python3.8/site-packages/urllib3/connectionpool.py", line 387, in _make_request
    conn.request(method, url, **httplib_request_kw)
  File "/usr/lib/python3.8/http/client.py", line 1255, in request
    self._send_request(method, url, body, headers, encode_chunked)
  File "/usr/lib/python3.8/http/client.py", line 1301, in _send_request
    self.endheaders(body, encode_chunked=encode_chunked)
  File "/usr/lib/python3.8/http/client.py", line 1250, in endheaders
    self._send_output(message_body, encode_chunked=encode_chunked)
  File "/usr/lib/python3.8/http/client.py", line 1010, in _send_output
    self.send(msg)
  File "/usr/lib/python3.8/http/client.py", line 950, in send
    self.connect()
  File "/home/rumi/Desktop/projects/django/job_env/lib/python3.8/site-packages/urllib3/connection.py", line 187, in connect
    conn = self._new_conn()
  File "/home/rumi/Desktop/projects/django/job_env/lib/python3.8/site-packages/urllib3/connection.py", line 171, in _new_conn
    raise NewConnectionError(
urllib3.exceptions.NewConnectionError: <urllib3.connection.HTTPConnection object at 0x7f721f6ca370>: Failed to establish a new connection: [Errno 111] Connection refused
Watching for file changes with StatReloader
Watching for file changes with StatReloader
Watching for file changes with StatReloader
Watching for file changes with StatReloader
Watching for file changes with StatReloader
Watching for file changes with StatReloader
Internal Server Error: /
Traceback (most recent call last):
  File "/home/rumi/Desktop/projects/django/job_env/lib/python3.8/site-packages/django/core/handlers/exception.py", line 34, in inner
    response = get_response(request)
  File "/home/rumi/Desktop/projects/django/job_env/lib/python3.8/site-packages/django/core/handlers/base.py", line 145, in _get_response
    response = self.process_exception_by_middleware(e, request)
  File "/home/rumi/Desktop/projects/django/job_env/lib/python3.8/site-packages/django/core/handlers/base.py", line 143, in _get_response
    response = response.render()
  File "/home/rumi/Desktop/projects/django/job_env/lib/python3.8/site-packages/django/template/response.py", line 105, in render
    self.content = self.rendered_content
  File "/home/rumi/Desktop/projects/django/job_env/lib/python3.8/site-packages/django/template/response.py", line 83, in rendered_content
    return template.render(context, self._request)
  File "/home/rumi/Desktop/projects/django/job_env/lib/python3.8/site-packages/django/template/backends/django.py", line 61, in render
    return self.template.render(context)
  File "/home/rumi/Desktop/projects/django/job_env/lib/python3.8/site-packages/django/template/base.py", line 171, in render
    return self._render(context)
  File "/home/rumi/Desktop/projects/django/job_env/lib/python3.8/site-packages/django/test/utils.py", line 95, in instrumented_test_render
    return self.nodelist.render(context)
  File "/home/rumi/Desktop/projects/django/job_env/lib/python3.8/site-packages/django/template/base.py", line 936, in render
    bit = node.render_annotated(context)
  File "/home/rumi/Desktop/projects/django/job_env/lib/python3.8/site-packages/django/template/base.py", line 903, in render_annotated
    return self.render(context)
  File "/home/rumi/Desktop/projects/django/job_env/lib/python3.8/site-packages/django/template/loader_tags.py", line 150, in render
    return compiled_parent._render(context)
  File "/home/rumi/Desktop/projects/django/job_env/lib/python3.8/site-packages/django/test/utils.py", line 95, in instrumented_test_render
    return self.nodelist.render(context)
  File "/home/rumi/Desktop/projects/django/job_env/lib/python3.8/site-packages/django/template/base.py", line 936, in render
    bit = node.render_annotated(context)
  File "/home/rumi/Desktop/projects/django/job_env/lib/python3.8/site-packages/django/template/base.py", line 903, in render_annotated
    return self.render(context)
  File "/home/rumi/Desktop/projects/django/job_env/lib/python3.8/site-packages/django/template/loader_tags.py", line 62, in render
    result = block.nodelist.render(context)
  File "/home/rumi/Desktop/projects/django/job_env/lib/python3.8/site-packages/django/template/base.py", line 936, in render
    bit = node.render_annotated(context)
  File "/home/rumi/Desktop/projects/django/job_env/lib/python3.8/site-packages/django/template/base.py", line 903, in render_annotated
    return self.render(context)
  File "/home/rumi/Desktop/projects/django/job_env/lib/python3.8/site-packages/django/templatetags/static.py", line 106, in render
    url = self.url(context)
  File "/home/rumi/Desktop/projects/django/job_env/lib/python3.8/site-packages/django/templatetags/static.py", line 103, in url
    return self.handle_simple(path)
  File "/home/rumi/Desktop/projects/django/job_env/lib/python3.8/site-packages/django/templatetags/static.py", line 118, in handle_simple
    return staticfiles_storage.url(path)
  File "/home/rumi/Desktop/projects/django/job_env/lib/python3.8/site-packages/django/contrib/staticfiles/storage.py", line 153, in url
    return self._url(self.stored_name, name, force)
  File "/home/rumi/Desktop/projects/django/job_env/lib/python3.8/site-packages/django/contrib/staticfiles/storage.py", line 132, in _url
    hashed_name = hashed_name_func(*args)
  File "/home/rumi/Desktop/projects/django/job_env/lib/python3.8/site-packages/django/contrib/staticfiles/storage.py", line 423, in stored_name
    raise ValueError("Missing staticfiles manifest entry for '%s'" % clean_name)
ValueError: Missing staticfiles manifest entry for 'img/startup.jpg'
Internal Server Error: /
Traceback (most recent call last):
  File "/home/rumi/Desktop/projects/django/job_env/lib/python3.8/site-packages/django/core/handlers/exception.py", line 34, in inner
    response = get_response(request)
  File "/home/rumi/Desktop/projects/django/job_env/lib/python3.8/site-packages/django/core/handlers/base.py", line 145, in _get_response
    response = self.process_exception_by_middleware(e, request)
  File "/home/rumi/Desktop/projects/django/job_env/lib/python3.8/site-packages/django/core/handlers/base.py", line 143, in _get_response
    response = response.render()
  File "/home/rumi/Desktop/projects/django/job_env/lib/python3.8/site-packages/django/template/response.py", line 105, in render
    self.content = self.rendered_content
  File "/home/rumi/Desktop/projects/django/job_env/lib/python3.8/site-packages/django/template/response.py", line 83, in rendered_content
    return template.render(context, self._request)
  File "/home/rumi/Desktop/projects/django/job_env/lib/python3.8/site-packages/django/template/backends/django.py", line 61, in render
    return self.template.render(context)
  File "/home/rumi/Desktop/projects/django/job_env/lib/python3.8/site-packages/django/template/base.py", line 171, in render
    return self._render(context)
  File "/home/rumi/Desktop/projects/django/job_env/lib/python3.8/site-packages/django/test/utils.py", line 95, in instrumented_test_render
    return self.nodelist.render(context)
  File "/home/rumi/Desktop/projects/django/job_env/lib/python3.8/site-packages/django/template/base.py", line 936, in render
    bit = node.render_annotated(context)
  File "/home/rumi/Desktop/projects/django/job_env/lib/python3.8/site-packages/django/template/base.py", line 903, in render_annotated
    return self.render(context)
  File "/home/rumi/Desktop/projects/django/job_env/lib/python3.8/site-packages/django/template/loader_tags.py", line 150, in render
    return compiled_parent._render(context)
  File "/home/rumi/Desktop/projects/django/job_env/lib/python3.8/site-packages/django/test/utils.py", line 95, in instrumented_test_render
    return self.nodelist.render(context)
  File "/home/rumi/Desktop/projects/django/job_env/lib/python3.8/site-packages/django/template/base.py", line 936, in render
    bit = node.render_annotated(context)
  File "/home/rumi/Desktop/projects/django/job_env/lib/python3.8/site-packages/django/template/base.py", line 903, in render_annotated
    return self.render(context)
  File "/home/rumi/Desktop/projects/django/job_env/lib/python3.8/site-packages/django/template/loader_tags.py", line 62, in render
    result = block.nodelist.render(context)
  File "/home/rumi/Desktop/projects/django/job_env/lib/python3.8/site-packages/django/template/base.py", line 936, in render
    bit = node.render_annotated(context)
  File "/home/rumi/Desktop/projects/django/job_env/lib/python3.8/site-packages/django/template/base.py", line 903, in render_annotated
    return self.render(context)
  File "/home/rumi/Desktop/projects/django/job_env/lib/python3.8/site-packages/django/templatetags/static.py", line 106, in render
    url = self.url(context)
  File "/home/rumi/Desktop/projects/django/job_env/lib/python3.8/site-packages/django/templatetags/static.py", line 103, in url
    return self.handle_simple(path)
  File "/home/rumi/Desktop/projects/django/job_env/lib/python3.8/site-packages/django/templatetags/static.py", line 118, in handle_simple
    return staticfiles_storage.url(path)
  File "/home/rumi/Desktop/projects/django/job_env/lib/python3.8/site-packages/django/contrib/staticfiles/storage.py", line 153, in url
    return self._url(self.stored_name, name, force)
  File "/home/rumi/Desktop/projects/django/job_env/lib/python3.8/site-packages/django/contrib/staticfiles/storage.py", line 132, in _url
    hashed_name = hashed_name_func(*args)
  File "/home/rumi/Desktop/projects/django/job_env/lib/python3.8/site-packages/django/contrib/staticfiles/storage.py", line 423, in stored_name
    raise ValueError("Missing staticfiles manifest entry for '%s'" % clean_name)
ValueError: Missing staticfiles manifest entry for 'img/startup.jpg'
Internal Server Error: /search
Traceback (most recent call last):
  File "/home/rumi/Desktop/projects/django/job_env/lib/python3.8/site-packages/django/utils/datastructures.py", line 76, in __getitem__
    list_ = super().__getitem__(key)
KeyError: 'location'

During handling of the above exception, another exception occurred:

Traceback (most recent call last):
  File "/home/rumi/Desktop/projects/django/job_env/lib/python3.8/site-packages/django/core/handlers/exception.py", line 34, in inner
    response = get_response(request)
  File "/home/rumi/Desktop/projects/django/job_env/lib/python3.8/site-packages/django/core/handlers/base.py", line 115, in _get_response
    response = self.process_exception_by_middleware(e, request)
  File "/home/rumi/Desktop/projects/django/job_env/lib/python3.8/site-packages/django/core/handlers/base.py", line 113, in _get_response
    response = wrapped_callback(request, *callback_args, **callback_kwargs)
  File "/home/rumi/Desktop/projects/django/job_env/lib/python3.8/site-packages/django/views/generic/base.py", line 71, in view
    return self.dispatch(request, *args, **kwargs)
  File "/home/rumi/Desktop/projects/django/job_env/lib/python3.8/site-packages/django/views/generic/base.py", line 97, in dispatch
    return handler(request, *args, **kwargs)
  File "/home/rumi/Desktop/projects/django/job_env/lib/python3.8/site-packages/django/views/generic/list.py", line 142, in get
    self.object_list = self.get_queryset()
  File "/home/rumi/Desktop/projects/django/job_env/portal/jobsapp/views/home.py", line 37, in get_queryset
    return self.model.objects.filter(location__contains=self.request.GET['location'],
  File "/home/rumi/Desktop/projects/django/job_env/lib/python3.8/site-packages/django/utils/datastructures.py", line 78, in __getitem__
    raise MultiValueDictKeyError(key)
django.utils.datastructures.MultiValueDictKeyError: 'location'
Internal Server Error: /search
Traceback (most recent call last):
  File "/home/rumi/Desktop/projects/django/job_env/lib/python3.8/site-packages/django/utils/datastructures.py", line 76, in __getitem__
    list_ = super().__getitem__(key)
KeyError: 'location'

During handling of the above exception, another exception occurred:

Traceback (most recent call last):
  File "/home/rumi/Desktop/projects/django/job_env/lib/python3.8/site-packages/django/core/handlers/exception.py", line 34, in inner
    response = get_response(request)
  File "/home/rumi/Desktop/projects/django/job_env/lib/python3.8/site-packages/django/core/handlers/base.py", line 115, in _get_response
    response = self.process_exception_by_middleware(e, request)
  File "/home/rumi/Desktop/projects/django/job_env/lib/python3.8/site-packages/django/core/handlers/base.py", line 113, in _get_response
    response = wrapped_callback(request, *callback_args, **callback_kwargs)
  File "/home/rumi/Desktop/projects/django/job_env/lib/python3.8/site-packages/django/views/generic/base.py", line 71, in view
    return self.dispatch(request, *args, **kwargs)
  File "/home/rumi/Desktop/projects/django/job_env/lib/python3.8/site-packages/django/views/generic/base.py", line 97, in dispatch
    return handler(request, *args, **kwargs)
  File "/home/rumi/Desktop/projects/django/job_env/lib/python3.8/site-packages/django/views/generic/list.py", line 142, in get
    self.object_list = self.get_queryset()
  File "/home/rumi/Desktop/projects/django/job_env/portal/jobsapp/views/home.py", line 37, in get_queryset
    return self.model.objects.filter(location__contains=self.request.GET['location'],
  File "/home/rumi/Desktop/projects/django/job_env/lib/python3.8/site-packages/django/utils/datastructures.py", line 78, in __getitem__
    raise MultiValueDictKeyError(key)
django.utils.datastructures.MultiValueDictKeyError: 'location'
Internal Server Error: /search
Traceback (most recent call last):
  File "/home/rumi/Desktop/projects/django/job_env/lib/python3.8/site-packages/django/core/handlers/exception.py", line 34, in inner
    response = get_response(request)
  File "/home/rumi/Desktop/projects/django/job_env/lib/python3.8/site-packages/django/core/handlers/base.py", line 115, in _get_response
    response = self.process_exception_by_middleware(e, request)
  File "/home/rumi/Desktop/projects/django/job_env/lib/python3.8/site-packages/django/core/handlers/base.py", line 113, in _get_response
    response = wrapped_callback(request, *callback_args, **callback_kwargs)
  File "/home/rumi/Desktop/projects/django/job_env/lib/python3.8/site-packages/django/views/generic/base.py", line 71, in view
    return self.dispatch(request, *args, **kwargs)
  File "/home/rumi/Desktop/projects/django/job_env/lib/python3.8/site-packages/django/views/generic/base.py", line 97, in dispatch
    return handler(request, *args, **kwargs)
  File "/home/rumi/Desktop/projects/django/job_env/lib/python3.8/site-packages/django/views/generic/list.py", line 142, in get
    self.object_list = self.get_queryset()
  File "/home/rumi/Desktop/projects/django/job_env/portal/jobsapp/views/home.py", line 37, in get_queryset
    return self.model.objects.filter(location__contains=self.request.GET.get('location', None),
  File "/home/rumi/Desktop/projects/django/job_env/lib/python3.8/site-packages/django/db/models/manager.py", line 82, in manager_method
    return getattr(self.get_queryset(), name)(*args, **kwargs)
  File "/home/rumi/Desktop/projects/django/job_env/lib/python3.8/site-packages/django/db/models/query.py", line 904, in filter
    return self._filter_or_exclude(False, *args, **kwargs)
  File "/home/rumi/Desktop/projects/django/job_env/lib/python3.8/site-packages/django/db/models/query.py", line 923, in _filter_or_exclude
    clone.query.add_q(Q(*args, **kwargs))
  File "/home/rumi/Desktop/projects/django/job_env/lib/python3.8/site-packages/django/db/models/sql/query.py", line 1351, in add_q
    clause, _ = self._add_q(q_object, self.used_aliases)
  File "/home/rumi/Desktop/projects/django/job_env/lib/python3.8/site-packages/django/db/models/sql/query.py", line 1378, in _add_q
    child_clause, needed_inner = self.build_filter(
  File "/home/rumi/Desktop/projects/django/job_env/lib/python3.8/site-packages/django/db/models/sql/query.py", line 1312, in build_filter
    condition = self.build_lookup(lookups, col, value)
  File "/home/rumi/Desktop/projects/django/job_env/lib/python3.8/site-packages/django/db/models/sql/query.py", line 1171, in build_lookup
    raise ValueError("Cannot use None as a query value")
ValueError: Cannot use None as a query value
Internal Server Error: /search
Traceback (most recent call last):
  File "/home/rumi/Desktop/projects/django/job_env/lib/python3.8/site-packages/django/core/handlers/exception.py", line 34, in inner
    response = get_response(request)
  File "/home/rumi/Desktop/projects/django/job_env/lib/python3.8/site-packages/django/core/handlers/base.py", line 115, in _get_response
    response = self.process_exception_by_middleware(e, request)
  File "/home/rumi/Desktop/projects/django/job_env/lib/python3.8/site-packages/django/core/handlers/base.py", line 113, in _get_response
    response = wrapped_callback(request, *callback_args, **callback_kwargs)
  File "/home/rumi/Desktop/projects/django/job_env/lib/python3.8/site-packages/django/views/generic/base.py", line 71, in view
    return self.dispatch(request, *args, **kwargs)
  File "/home/rumi/Desktop/projects/django/job_env/lib/python3.8/site-packages/django/views/generic/base.py", line 97, in dispatch
    return handler(request, *args, **kwargs)
  File "/home/rumi/Desktop/projects/django/job_env/lib/python3.8/site-packages/django/views/generic/list.py", line 142, in get
    self.object_list = self.get_queryset()
  File "/home/rumi/Desktop/projects/django/job_env/portal/jobsapp/views/home.py", line 37, in get_queryset
    return self.model.objects.filter(location__contains=self.request.GET.get('location', None),
  File "/home/rumi/Desktop/projects/django/job_env/lib/python3.8/site-packages/django/db/models/manager.py", line 82, in manager_method
    return getattr(self.get_queryset(), name)(*args, **kwargs)
  File "/home/rumi/Desktop/projects/django/job_env/lib/python3.8/site-packages/django/db/models/query.py", line 904, in filter
    return self._filter_or_exclude(False, *args, **kwargs)
  File "/home/rumi/Desktop/projects/django/job_env/lib/python3.8/site-packages/django/db/models/query.py", line 923, in _filter_or_exclude
    clone.query.add_q(Q(*args, **kwargs))
  File "/home/rumi/Desktop/projects/django/job_env/lib/python3.8/site-packages/django/db/models/sql/query.py", line 1351, in add_q
    clause, _ = self._add_q(q_object, self.used_aliases)
  File "/home/rumi/Desktop/projects/django/job_env/lib/python3.8/site-packages/django/db/models/sql/query.py", line 1378, in _add_q
    child_clause, needed_inner = self.build_filter(
  File "/home/rumi/Desktop/projects/django/job_env/lib/python3.8/site-packages/django/db/models/sql/query.py", line 1312, in build_filter
    condition = self.build_lookup(lookups, col, value)
  File "/home/rumi/Desktop/projects/django/job_env/lib/python3.8/site-packages/django/db/models/sql/query.py", line 1171, in build_lookup
    raise ValueError("Cannot use None as a query value")
ValueError: Cannot use None as a query value
Not Found: /jobs/1
Not Found: /jobs/1
Not Found: /jobs/1
Not Found: /jobs/1
Not Found: /jobs/1
Not Found: /jobs/1
